Workbook

Sheet PAINEL ENTRADA
A1: SÃO FRANCISCO | T1: =A1 -> SÃO FRANCISCO

Sheet SÃO FRANCISCO
A1: MOVIMENTAÇÃO FAZENDA SÃO FRANCISCO | S1: COMPRA
D2: ENTRADAS | J2: SAIDAS | O2: POSIÇÃO | S2: NASC.
S3: TRANSF. E
A4: CATEGORIAS | D4: SALDO ANTERIOR | E4: COMPRA | F4: EVOLUÇ | G4: NASC. | H4: TRANSF. E | I4: TOTAL | J4: ABATE | K4: MORTE | L4: VENDA | M4: TRANSF. S | N4: TOTAL | O4: FINAL | S4: ABATE
A5: Femeas + 36 meses | E5: =SUMIFS($E$20:$E$1048576,$D$20:$D$1048576,$E$4,$C$20:$C$1048576,A5) -> 0 | F5: =SUMIFS($E$20:$E$1048576,$D$20:$D$1048576,$F$4,$C$20:$C$1048576,B5) -> 0 | G5: =SUMIFS($E$20:$E$1048576,$D$20:$D$1048576,$G$4,$C$20:$C$1048576,A5) -> 0 | H5: =SUMIFS($E$20:$E$1048576,$D$20:$D$1048576,$H$4,$C$20:$C$1048576,A5) -> 0 | I5: =SUM(D5:H5) -> 0 | J5: =SUMIFS($E$20:$E$1048576,$D$20:$D$1048576,$J$4,$C$20:$C$1048576,A5) -> 0 | K5: =SUMIFS($E$20:$E$1048576,$D$20:$D$1048576,$K$4,$C$20:$C$1048576,A5) -> 0 | L5: =SUMIFS($E$20:$E$1048576,$D$20:$D$1048576,$L$4,$C$20:$C$1048576,A5) -> 0 | M5: =SUMIFS($E$20:$E$1048576,$D$20:$D$1048576,$M$4,$C$20:$C$1048576,A5) -> 0 | N5: =SUM(J5:M5) -> 0 | O5: =SUM(I5-N5) -> 0 | S5: MORTE
A6: Femeas 25 a 36 meses | E6: =SUMIFS($E$20:$E$1048576,$D$20:$D$1048576,$E$4,$C$20:$C$1048576,A6) -> 0 | F6: =SUMIFS($E$20:$E$1048576,$D$20:$D$1048576,$F$4,$C$20:$C$1048576,B6) -> 0 | G6: =SUMIFS($E$20:$E$1048576,$D$20:$D$1048576,$G$4,$C$20:$C$1048576,A6) -> 0 | H6: =SUMIFS($E$20:$E$1048576,$D$20:$D$1048576,$H$4,$C$20:$C$1048576,A6) -> 0 | I6: =SUM(D6:H6) -> 0 | J6: =SUMIFS($E$20:$E$1048576,$D$20:$D$1048576,$J$4,$C$20:$C$1048576,A6) -> 0 | K6: =SUMIFS($E$20:$E$1048576,$D$20:$D$1048576,$K$4,$C$20:$C$1048576,A6) -> 0 | L6: =SUMIFS($E$20:$E$1048576,$D$20:$D$1048576,$L$4,$C$20:$C$1048576,A6) -> 0 | M6: =SUMIFS($E$20:$E$1048576,$D$20:$D$1048576,$M$4,$C$20:$C$1048576,A6) -> 0 | N6: =SUM(J6:M6) -> 0 | O6: =SUM(I6-N6) -> 0 | S6: TRANSF. S
A7: Femeas 13 a 24 meses | E7: =SUMIFS($E$20:$E$1048576,$D$20:$D$1048576,$E$4,$C$20:$C$1048576,A7) -> 0 | F7: =SUMIFS($E$20:$E$1048576,$D$20:$D$1048576,$F$4,$C$20:$C$1048576,B7) -> 0 | G7: =SUMIFS($E$20:$E$1048576,$D$20:$D$1048576,$G$4,$C$20:$C$1048576,A7) -> 0 | H7: =SUMIFS($E$20:$E$1048576,$D$20:$D$1048576,$H$4,$C$20:$C$1048576,A7) -> 0 | I7: =SUM(D7:H7) -> 0 | J7: =SUMIFS($E$20:$E$1048576,$D$20:$D$1048576,$J$4,$C$20:$C$1048576,A7) -> 0 | K7: =SUMIFS($E$20:$E$1048576,$D$20:$D$1048576,$K$4,$C$20:$C$1048576,A7) -> 0 | L7: =SUMIFS($E$20:$E$1048576,$D$20:$D$1048576,$L$4,$C$20:$C$1048576,A7) -> 0 | M7: =SUMIFS($E$20:$E$1048576,$D$20:$D$1048576,$M$4,$C$20:$C$1048576,A7) -> 0 | N7: =SUM(J7:M7) -> 0 | O7: =SUM(I7-N7) -> 0 | S7: SALDO ANTERIOR
A8: Femeas Desm. até 12m | E8: =SUMIFS($E$20:$E$1048576,$D$20:$D$1048576,$E$4,$C$20:$C$1048576,A8) -> 0 | F8: =SUMIFS($E$20:$E$1048576,$D$20:$D$1048576,$F$4,$C$20:$C$1048576,B8) -> 0 | G8: =SUMIFS($E$20:$E$1048576,$D$20:$D$1048576,$G$4,$C$20:$C$1048576,A8) -> 0 | H8: =SUMIFS($E$20:$E$1048576,$D$20:$D$1048576,$H$4,$C$20:$C$1048576,A8) -> 0 | I8: =SUM(D8:H8) -> 0 | J8: =SUMIFS($E$20:$E$1048576,$D$20:$D$1048576,$J$4,$C$20:$C$1048576,A8) -> 0 | K8: =SUMIFS($E$20:$E$1048576,$D$20:$D$1048576,$K$4,$C$20:$C$1048576,A8) -> 0 | L8: =SUMIFS($E$20:$E$1048576,$D$20:$D$1048576,$L$4,$C$20:$C$1048576,A8) -> 0 | M8: =SUMIFS($E$20:$E$1048576,$D$20:$D$1048576,$M$4,$C$20:$C$1048576,A8) -> 0 | N8: =SUM(J8:M8) -> 0 | O8: =SUM(I8-N8) -> 0 | S8: EVOLUÇ
A9: Bezerras Mamando | E9: =SUMIFS($E$20:$E$1048576,$D$20:$D$1048576,$E$4,$C$20:$C$1048576,A9) -> 0 | F9: =SUMIFS($E$20:$E$1048576,$D$20:$D$1048576,$F$4,$C$20:$C$1048576,B9) -> 0 | G9: =SUMIFS($E$20:$E$1048576,$D$20:$D$1048576,$G$4,$C$20:$C$1048576,A9) -> 0 | H9: =SUMIFS($E$20:$E$1048576,$D$20:$D$1048576,$H$4,$C$20:$C$1048576,A9) -> 0 | I9: =SUM(D9:H9) -> 0 | J9: =SUMIFS($E$20:$E$1048576,$D$20:$D$1048576,$J$4,$C$20:$C$1048576,A9) -> 0 | K9: =SUMIFS($E$20:$E$1048576,$D$20:$D$1048576,$K$4,$C$20:$C$1048576,A9) -> 0 | L9: =SUMIFS($E$20:$E$1048576,$D$20:$D$1048576,$L$4,$C$20:$C$1048576,A9) -> 0 | M9: =SUMIFS($E$20:$E$1048576,$D$20:$D$1048576,$M$4,$C$20:$C$1048576,A9) -> 0 | N9: =SUM(J9:M9) -> 0 | O9: =SUM(I9-N9) -> 0 | S9: VENDA
A10: Bezerros Mamando | E10: =SUMIFS($E$20:$E$1048576,$D$20:$D$1048576,$E$4,$C$20:$C$1048576,A10) -> 0 | F10: =SUMIFS($E$20:$E$1048576,$D$20:$D$1048576,$F$4,$C$20:$C$1048576,B10) -> 0 | G10: =SUMIFS($E$20:$E$1048576,$D$20:$D$1048576,$G$4,$C$20:$C$1048576,A10) -> 0 | H10: =SUMIFS($E$20:$E$1048576,$D$20:$D$1048576,$H$4,$C$20:$C$1048576,A10) -> 0 | I10: =SUM(D10:H10) -> 0 | J10: =SUMIFS($E$20:$E$1048576,$D$20:$D$1048576,$J$4,$C$20:$C$1048576,A10) -> 0 | K10: =SUMIFS($E$20:$E$1048576,$D$20:$D$1048576,$K$4,$C$20:$C$1048576,A10) -> 0 | L10: =SUMIFS($E$20:$E$1048576,$D$20:$D$1048576,$L$4,$C$20:$C$1048576,A10) -> 0 | M10: =SUMIFS($E$20:$E$1048576,$D$20:$D$1048576,$M$4,$C$20:$C$1048576,A10) -> 0 | N10: =SUM(J10:M10) -> 0 | O10: =SUM(I10-N10) -> 0
A11: Machos Desm. até 12m | D11: 552 | E11: =SUMIFS($E$20:$E$1048576,$D$20:$D$1048576,$E$4,$C$20:$C$1048576,A11) -> 828 | F11: =SUMIFS($E$20:$E$1048576,$D$20:$D$1048576,$F$4,$C$20:$C$1048576,B11) -> 0 | G11: =SUMIFS($E$20:$E$1048576,$D$20:$D$1048576,$G$4,$C$20:$C$1048576,A11) -> 0 | H11: =SUMIFS($E$20:$E$1048576,$D$20:$D$1048576,$H$4,$C$20:$C$1048576,A11) -> 0 | I11: =SUM(D11:H11) -> 1380 | J11: =SUMIFS($E$20:$E$1048576,$D$20:$D$1048576,$J$4,$C$20:$C$1048576,A11) -> 0 | K11: =SUMIFS($E$20:$E$1048576,$D$20:$D$1048576,$K$4,$C$20:$C$1048576,A11) -> 12 | L11: =SUMIFS($E$20:$E$1048576,$D$20:$D$1048576,$L$4,$C$20:$C$1048576,A11) -> 0 | M11: =SUMIFS($E$20:$E$1048576,$D$20:$D$1048576,$M$4,$C$20:$C$1048576,A11) -> 0 | N11: =SUM(J11:M11) -> 12 | O11: =SUM(I11-N11) -> 1368 | P11: ANIMAIS ABAIXO DE 8 @
A12: Machos 13 a 24 meses | D12: 171 | E12: =SUMIFS($E$20:$E$1048576,$D$20:$D$1048576,$E$4,$C$20:$C$1048576,A12) -> 0 | F12: =SUMIFS($E$20:$E$1048576,$D$20:$D$1048576,$F$4,$C$20:$C$1048576,B12) -> 0 | G12: =SUMIFS($E$20:$E$1048576,$D$20:$D$1048576,$G$4,$C$20:$C$1048576,A12) -> 0 | H12: =SUMIFS($E$20:$E$1048576,$D$20:$D$1048576,$H$4,$C$20:$C$1048576,A12) -> 0 | I12: =SUM(D12:H12) -> 171 | J12: =SUMIFS($E$20:$E$1048576,$D$20:$D$1048576,$J$4,$C$20:$C$1048576,A12) -> 0 | K12: =SUMIFS($E$20:$E$1048576,$D$20:$D$1048576,$K$4,$C$20:$C$1048576,A12) -> 8 | L12: =SUMIFS($E$20:$E$1048576,$D$20:$D$1048576,$L$4,$C$20:$C$1048576,A12) -> 0 | M12: =SUMIFS($E$20:$E$1048576,$D$20:$D$1048576,$M$4,$C$20:$C$1048576,A12) -> 0 | N12: =SUM(J12:M12) -> 8 | O12: =SUM(I12-N12) -> 163 | P12: ANIMAIS DE 8 A 12 @
A13: Machos 25 a 36 meses | D13: 780 | E13: =SUMIFS($E$20:$E$1048576,$D$20:$D$1048576,$E$4,$C$20:$C$1048576,A13) -> 0 | F13: =SUMIFS($E$20:$E$1048576,$D$20:$D$1048576,$F$4,$C$20:$C$1048576,B13) -> 0 | G13: =SUMIFS($E$20:$E$1048576,$D$20:$D$1048576,$G$4,$C$20:$C$1048576,A13) -> 0 | H13: =SUMIFS($E$20:$E$1048576,$D$20:$D$1048576,$H$4,$C$20:$C$1048576,A13) -> 0 | I13: =SUM(D13:H13) -> 780 | J13: =SUMIFS($E$20:$E$1048576,$D$20:$D$1048576,$J$4,$C$20:$C$1048576,A13) -> 354 | K13: =SUMIFS($E$20:$E$1048576,$D$20:$D$1048576,$K$4,$C$20:$C$1048576,A13) -> 3 | L13: =SUMIFS($E$20:$E$1048576,$D$20:$D$1048576,$L$4,$C$20:$C$1048576,A13) -> 0 | M13: =SUMIFS($E$20:$E$1048576,$D$20:$D$1048576,$M$4,$C$20:$C$1048576,A13) -> 0 | N13: =SUM(J13:M13) -> 357 | O13: =SUM(I13-N13) -> 423 | P13: ANIMAIS ACIMA DE 12 @
A14: Touros | E14: =SUMIFS($E$20:$E$1048576,$D$20:$D$1048576,$E$4,$C$20:$C$1048576,A14) -> 0 | F14: =SUMIFS($E$20:$E$1048576,$D$20:$D$1048576,$F$4,$C$20:$C$1048576,B14) -> 0 | G14: =SUMIFS($E$20:$E$1048576,$D$20:$D$1048576,$G$4,$C$20:$C$1048576,A14) -> 0 | H14: =SUMIFS($E$20:$E$1048576,$D$20:$D$1048576,$H$4,$C$20:$C$1048576,A14) -> 0 | I14: =SUM(D14:H14) -> 0 | J14: =SUMIFS($E$20:$E$1048576,$D$20:$D$1048576,$J$4,$C$20:$C$1048576,A14) -> 0 | K14: =SUMIFS($E$20:$E$1048576,$D$20:$D$1048576,$K$4,$C$20:$C$1048576,A14) -> 0 | L14: =SUMIFS($E$20:$E$1048576,$D$20:$D$1048576,$L$4,$C$20:$C$1048576,A14) -> 0 | M14: =SUMIFS($E$20:$E$1048576,$D$20:$D$1048576,$M$4,$C$20:$C$1048576,A14) -> 0 | N14: =SUM(J14:M14) -> 0 | O14: =SUM(I14-N14) -> 0
A15: TROPA | E15: =SUMIFS($E$20:$E$1048576,$D$20:$D$1048576,$E$4,$C$20:$C$1048576,A15) -> 0 | F15: 0 | G15: =SUMIFS($E$20:$E$1048576,$D$20:$D$1048576,$G$4,$C$20:$C$1048576,A15) -> 0 | H15: =SUMIFS($E$20:$E$1048576,$D$20:$D$1048576,$H$4,$C$20:$C$1048576,A15) -> 0 | I15: =SUM(D15:H15) -> 0 | J15: =SUMIFS($E$20:$E$1048576,$D$20:$D$1048576,$J$4,$C$20:$C$1048576,A15) -> 0 | K15: =SUMIFS($E$20:$E$1048576,$D$20:$D$1048576,$K$4,$C$20:$C$1048576,A15) -> 0 | L15: =SUMIFS($E$20:$E$1048576,$D$20:$D$1048576,$L$4,$C$20:$C$1048576,A15) -> 0 | M15: =SUMIFS($E$20:$E$1048576,$D$20:$D$1048576,$M$4,$C$20:$C$1048576,A15) -> 0 | N15: =SUM(J15:M15) -> 0 | O15: =SUM(I15-N15) -> 0
A16: TOTAL | D16: =SUM(D5:D15) -> 1503 | E16: =SUM(E5:E15) -> 828 | F16: =SUM(F5:F15) -> 0 | G16: =SUM(G5:G15) -> 0 | H16: =SUM(H5:H15) -> 0 | I16: =SUM(I5:I15) -> 2331 | J16: =SUM(J5:J15) -> 354 | K16: =SUM(K5:K15) -> 23 | ... O16: =SUM(O5:O15) -> 1954
A18: MOVIMENTAÇÕES DE BOVINOS
A19: DATA | B19: MÊS | C19: CATEGORIA | D19: TIPO | E19: QUANTIDADE | F19: SAIDA | G19: DESTINO | H19: PESO TOTAL | I19: PESO MÉDIO
A20: 45852 | B20: =TEXT(Tabela2234[[#This Row],[DATA]],"mmm") -> jul | C20: Machos Desm. até 12m | D20: MORTE | E20: 1 | F20: MORTE | G20: MORTE | H20: 150 | I20: =Tabela2234[[#This Row],[PESO TOTAL]]/Tabela2234[[#This Row],[QUANTIDADE]] -> 150
A21: 45855 | B21: =TEXT(Tabela2234[[#This Row],[DATA]],"mmm") -> jul | C21: Machos Desm. até 12m | D21: MORTE | E21: 1 | F21: MORTE | G21: MORTE | H21: 150 | I21: =Tabela2234[[#This Row],[PESO TOTAL]]/Tabela2234[[#This Row],[QUANTIDADE]] -> 150
A22: 45872 | B22: =TEXT(Tabela2234[[#This Row],[DATA]],"mmm") -> ago | C22: Machos 25 a 36 meses | D22: ABATE | E22: 84 | F22: ABATE | G22: COPERFRIGU | H22: 47040 | I22: =Tabela2234[[#This Row],[PESO TOTAL]]/Tabela2234[[#This Row],[QUANTIDADE]] -> 560
A23: 45860 | B23: =TEXT(Tabela2234[[#This Row],[DATA]],"mmm") -> jul | C23: Machos Desm. até 12m | D23: COMPRA | E23: 1 | F23: COMPRA | G23: ENTREGA COMPRA | H23: 150 | I23: =Tabela2234[[#This Row],[PESO TOTAL]]/Tabela2234[[#This Row],[QUANTIDADE]] -> 150
A24: 45909 | B24: =TEXT(Tabela2234[[#This Row],[DATA]],"mmm") -> set | C24: Machos Desm. até 12m | D24: COMPRA | E24: 133 | F24: COMPRA | G24: COMPRA GOIANO | H24: 27668 | I24: =Tabela2234[[#This Row],[PESO TOTAL]]/Tabela2234[[#This Row],[QUANTIDADE]] -> 208.03008
A25: 45894 | B25: =TEXT(Tabela2234[[#This Row],[DATA]],"mmm") -> ago | C25: Machos Desm. até 12m | D25: MORTE | E25: 1 | F25: MORTE | I25: =Tabela2234[[#This Row],[PESO TOTAL]]/Tabela2234[[#This Row],[QUANTIDADE]] -> 0
A26: 45898 | B26: =TEXT(Tabela2234[[#This Row],[DATA]],"mmm") -> ago | C26: Machos Desm. até 12m | D26: COMPRA | E26: 2 | G26: COMPRA GOIANO | H26: 416 | I26: =Tabela2234[[#This Row],[PESO TOTAL]]/Tabela2234[[#This Row],[QUANTIDADE]] -> 208
A27: 45908 | B27: =TEXT(Tabela2234[[#This Row],[DATA]],"mmmm") -> setembro | C27: Machos Desm. até 12m | D27: MORTE | E27: 1 | I27: =Tabela2234[[#This Row],[PESO TOTAL]]/Tabela2234[[#This Row],[QUANTIDADE]] -> 0
A28: 45947 | B28: =TEXT(Tabela2234[[#This Row],[DATA]],"mmmm") -> outubro | C28: Machos 13 a 24 meses | D28: MORTE | E28: 1 | I28: =Tabela2234[[#This Row],[PESO TOTAL]]/Tabela2234[[#This Row],[QUANTIDADE]] -> 0
A29: 45947 | B29: =TEXT(Tabela2234[[#This Row],[DATA]],"mmmm") -> outubro | C29: Machos Desm. até 12m | D29: COMPRA | E29: 12 | F29: COMPRA | H29: 1775 | I29: =Tabela2234[[#This Row],[PESO TOTAL]]/Tabela2234[[#This Row],[QUANTIDADE]] -> 147.91667
A30: 45950 | B30: =TEXT(Tabela2234[[#This Row],[DATA]],"mmmm") -> outubro | C30: Machos 25 a 36 meses | D30: MORTE | E30: 1 | G30: CANTINA | I30: =Tabela2234[[#This Row],[PESO TOTAL]]/Tabela2234[[#This Row],[QUANTIDADE]] -> 0
A31: 45953 | B31: =TEXT(Tabela2234[[#This Row],[DATA]],"mmmm") -> outubro | C31: Machos Desm. até 12m | D31: COMPRA | E31: 42 | F31: COMPRA | H31: 5647 | I31: =Tabela2234[[#This Row],[PESO TOTAL]]/Tabela2234[[#This Row],[QUANTIDADE]] -> 134.45238
A32: 45959 | B32: =TEXT(Tabela2234[[#This Row],[DATA]],"mmmm") -> outubro | C32: Machos Desm. até 12m | D32: MORTE | E32: 1 | I32: =Tabela2234[[#This Row],[PESO TOTAL]]/Tabela2234[[#This Row],[QUANTIDADE]] -> 0
A33: 45974 | B33: =TEXT(Tabela2234[[#This Row],[DATA]],"mmmm") -> novembro | C33: Machos Desm. até 12m | D33: MORTE | E33: 1 | I33: =Tabela2234[[#This Row],[PESO TOTAL]]/Tabela2234[[#This Row],[QUANTIDADE]] -> 0
A34: 45982 | B34: =TEXT(Tabela2234[[#This Row],[DATA]],"mmmm") -> novembro | C34: Machos Desm. até 12m | D34: COMPRA | E34: 150 | F34: COMPRA | H34: 22279 | I34: =Tabela2234[[#This Row],[PESO TOTAL]]/Tabela2234[[#This Row],[QUANTIDADE]] -> 148.52667
A35: 45985 | B35: =TEXT(Tabela2234[[#This Row],[DATA]],"mmmm") -> novembro | C35: Machos Desm. até 12m | D35: MORTE | E35: 1 | I35: =Tabela2234[[#This Row],[PESO TOTAL]]/Tabela2234[[#This Row],[QUANTIDADE]] -> 0
A36: 45988 | B36: =TEXT(Tabela2234[[#This Row],[DATA]],"mmmm") -> novembro | C36: Machos Desm. até 12m | D36: COMPRA | E36: 40 | F36: COMPRA | H36: 5941 | I36: =Tabela2234[[#This Row],[PESO TOTAL]]/Tabela2234[[#This Row],[QUANTIDADE]] -> 148.525
A37: 45999 | B37: =TEXT(Tabela2234[[#This Row],[DATA]],"mmmm") -> dezembro | C37: Machos Desm. até 12m | D37: MORTE | E37: 1 | I37: =Tabela2234[[#This Row],[PESO TOTAL]]/Tabela2234[[#This Row],[QUANTIDADE]] -> 0
A38: 46000 | B38: =TEXT(Tabela2234[[#This Row],[DATA]],"mmmm") -> dezembro | C38: Machos Desm. até 12m | D38: MORTE | E38: 1 | I38: =Tabela2234[[#This Row],[PESO TOTAL]]/Tabela2234[[#This Row],[QUANTIDADE]] -> 0
A39: 46004 | B39: =TEXT(Tabela2234[[#This Row],[DATA]],"mmmm") -> dezembro | C39: Machos Desm. até 12m | D39: MORTE | E39: 1 | I39: =Tabela2234[[#This Row],[PESO TOTAL]]/Tabela2234[[#This Row],[QUANTIDADE]] -> 0
A40: 46006 | B40: =TEXT(Tabela2234[[#This Row],[DATA]],"mmmm") -> dezembro | C40: Machos 13 a 24 meses | D40: MORTE | E40: 1 | I40: =Tabela2234[[#This Row],[PESO TOTAL]]/Tabela2234[[#This Row],[QUANTIDADE]] -> 0
A41: 46021 | B41: =TEXT(Tabela2234[[#This Row],[DATA]],"mmmm") -> dezembro | C41: Machos Desm. até 12m | D41: COMPRA | E41: 105 | F41: COMPRA | H41: 18345 | I41: =Tabela2234[[#This Row],[PESO TOTAL]]/Tabela2234[[#This Row],[QUANTIDADE]] -> 174.71429
...

Sheet GOIANO
A1: MOVIMENTAÇÃO FAZENDA GOIANO | S1: COMPRA
D2: ENTRADAS | J2: SAIDAS | O2: POSIÇÃO | S2: NASC.
S3: TRANSF. E
A4: CATEGORIAS | D4: SALDO ANTERIOR | E4: COMPRA | F4: EVOLUÇ | G4: NASC. | H4: TRANSF. E | I4: TOTAL | J4: ABATE | K4: MORTE | L4: VENDA | M4: TRANSF. S | N4: TOTAL | O4: FINAL | S4: ABATE
A5: Femeas + 36 meses | E5: =SUMIFS($E$20:$E$1048576,$D$20:$D$1048576,$E$4,$C$20:$C$1048576,A5) -> 0 | F5: =SUMIFS($E$20:$E$1048576,$D$20:$D$1048576,$F$4,$C$20:$C$1048576,B5) -> 0 | G5: =SUMIFS($E$20:$E$1048576,$D$20:$D$1048576,$G$4,$C$20:$C$1048576,A5) -> 0 | H5: =SUMIFS($E$20:$E$1048576,$D$20:$D$1048576,$H$4,$C$20:$C$1048576,A5) -> 0 | I5: =SUM(D5:H5) -> 0 | J5: =SUMIFS($E$20:$E$1048576,$D$20:$D$1048576,$J$4,$C$20:$C$1048576,A5) -> 0 | K5: =SUMIFS($E$20:$E$1048576,$D$20:$D$1048576,$K$4,$C$20:$C$1048576,A5) -> 0 | L5: =SUMIFS($E$20:$E$1048576,$D$20:$D$1048576,$L$4,$C$20:$C$1048576,A5) -> 0 | M5: =SUMIFS($E$20:$E$1048576,$D$20:$D$1048576,$M$4,$C$20:$C$1048576,A5) -> 0 | N5: =SUM(J5:M5) -> 0 | O5: =SUM(I5-N5) -> 0 | S5: MORTE
A6: Femeas 25 a 36 meses | E6: =SUMIFS($E$20:$E$1048576,$D$20:$D$1048576,$E$4,$C$20:$C$1048576,A6) -> 0 | F6: =SUMIFS($E$20:$E$1048576,$D$20:$D$1048576,$F$4,$C$20:$C$1048576,B6) -> 0 | G6: =SUMIFS($E$20:$E$1048576,$D$20:$D$1048576,$G$4,$C$20:$C$1048576,A6) -> 0 | H6: =SUMIFS($E$20:$E$1048576,$D$20:$D$1048576,$H$4,$C$20:$C$1048576,A6) -> 0 | I6: =SUM(D6:H6) -> 0 | J6: =SUMIFS($E$20:$E$1048576,$D$20:$D$1048576,$J$4,$C$20:$C$1048576,A6) -> 0 | K6: =SUMIFS($E$20:$E$1048576,$D$20:$D$1048576,$K$4,$C$20:$C$1048576,A6) -> 0 | L6: =SUMIFS($E$20:$E$1048576,$D$20:$D$1048576,$L$4,$C$20:$C$1048576,A6) -> 0 | M6: =SUMIFS($E$20:$E$1048576,$D$20:$D$1048576,$M$4,$C$20:$C$1048576,A6) -> 0 | N6: =SUM(J6:M6) -> 0 | O6: =SUM(I6-N6) -> 0 | S6: TRANSF. S
A7: Femeas 13 a 24 meses | E7: =SUMIFS($E$20:$E$1048576,$D$20:$D$1048576,$E$4,$C$20:$C$1048576,A7) -> 0 | F7: =SUMIFS($E$20:$E$1048576,$D$20:$D$1048576,$F$4,$C$20:$C$1048576,B7) -> 0 | G7: =SUMIFS($E$20:$E$1048576,$D$20:$D$1048576,$G$4,$C$20:$C$1048576,A7) -> 0 | H7: =SUMIFS($E$20:$E$1048576,$D$20:$D$1048576,$H$4,$C$20:$C$1048576,A7) -> 0 | I7: =SUM(D7:H7) -> 0 | J7: =SUMIFS($E$20:$E$1048576,$D$20:$D$1048576,$J$4,$C$20:$C$1048576,A7) -> 0 | K7: =SUMIFS($E$20:$E$1048576,$D$20:$D$1048576,$K$4,$C$20:$C$1048576,A7) -> 0 | L7: =SUMIFS($E$20:$E$1048576,$D$20:$D$1048576,$L$4,$C$20:$C$1048576,A7) -> 0 | M7: =SUMIFS($E$20:$E$1048576,$D$20:$D$1048576,$M$4,$C$20:$C$1048576,A7) -> 0 | N7: =SUM(J7:M7) -> 0 | O7: =SUM(I7-N7) -> 0 | S7: SALDO ANTERIOR
A8: Femeas Desm. até 12m | E8: =SUMIFS($E$20:$E$1048576,$D$20:$D$1048576,$E$4,$C$20:$C$1048576,A8) -> 0 | F8: =SUMIFS($E$20:$E$1048576,$D$20:$D$1048576,$F$4,$C$20:$C$1048576,B8) -> 0 | G8: =SUMIFS($E$20:$E$1048576,$D$20:$D$1048576,$G$4,$C$20:$C$1048576,A8) -> 0 | H8: =SUMIFS($E$20:$E$1048576,$D$20:$D$1048576,$H$4,$C$20:$C$1048576,A8) -> 0 | I8: =SUM(D8:H8) -> 0 | J8: =SUMIFS($E$20:$E$1048576,$D$20:$D$1048576,$J$4,$C$20:$C$1048576,A8) -> 0 | K8: =SUMIFS($E$20:$E$1048576,$D$20:$D$1048576,$K$4,$C$20:$C$1048576,A8) -> 0 | L8: =SUMIFS($E$20:$E$1048576,$D$20:$D$1048576,$L$4,$C$20:$C$1048576,A8) -> 0 | M8: =SUMIFS($E$20:$E$1048576,$D$20:$D$1048576,$M$4,$C$20:$C$1048576,A8) -> 0 | N8: =SUM(J8:M8) -> 0 | O8: =SUM(I8-N8) -> 0 | S8: EVOLUÇ
A9: Bezerras Mamando | E9: =SUMIFS($E$20:$E$1048576,$D$20:$D$1048576,$E$4,$C$20:$C$1048576,A9) -> 0 | F9: =SUMIFS($E$20:$E$1048576,$D$20:$D$1048576,$F$4,$C$20:$C$1048576,B9) -> 0 | G9: =SUMIFS($E$20:$E$1048576,$D$20:$D$1048576,$G$4,$C$20:$C$1048576,A9) -> 0 | H9: =SUMIFS($E$20:$E$1048576,$D$20:$D$1048576,$H$4,$C$20:$C$1048576,A9) -> 0 | I9: =SUM(D9:H9) -> 0 | J9: =SUMIFS($E$20:$E$1048576,$D$20:$D$1048576,$J$4,$C$20:$C$1048576,A9) -> 0 | K9: =SUMIFS($E$20:$E$1048576,$D$20:$D$1048576,$K$4,$C$20:$C$1048576,A9) -> 0 | L9: =SUMIFS($E$20:$E$1048576,$D$20:$D$1048576,$L$4,$C$20:$C$1048576,A9) -> 0 | M9: =SUMIFS($E$20:$E$1048576,$D$20:$D$1048576,$M$4,$C$20:$C$1048576,A9) -> 0 | N9: =SUM(J9:M9) -> 0 | O9: =SUM(I9-N9) -> 0 | S9: VENDA
A10: Bezerros Mamando | E10: =SUMIFS($E$20:$E$1048576,$D$20:$D$1048576,$E$4,$C$20:$C$1048576,A10) -> 0 | F10: =SUMIFS($E$20:$E$1048576,$D$20:$D$1048576,$F$4,$C$20:$C$1048576,B10) -> 0 | G10: =SUMIFS($E$20:$E$1048576,$D$20:$D$1048576,$G$4,$C$20:$C$1048576,A10) -> 0 | H10: =SUMIFS($E$20:$E$1048576,$D$20:$D$1048576,$H$4,$C$20:$C$1048576,A10) -> 0 | I10: =SUM(D10:H10) -> 0 | J10: =SUMIFS($E$20:$E$1048576,$D$20:$D$1048576,$J$4,$C$20:$C$1048576,A10) -> 0 | K10: =SUMIFS($E$20:$E$1048576,$D$20:$D$1048576,$K$4,$C$20:$C$1048576,A10) -> 0 | L10: =SUMIFS($E$20:$E$1048576,$D$20:$D$1048576,$L$4,$C$20:$C$1048576,A10) -> 0 | M10: =SUMIFS($E$20:$E$1048576,$D$20:$D$1048576,$M$4,$C$20:$C$1048576,A10) -> 0 | N10: =SUM(J10:M10) -> 0 | O10: =SUM(I10-N10) -> 0
A11: Machos Desm. até 12m | E11: =SUMIFS($E$20:$E$1048576,$D$20:$D$1048576,$E$4,$C$20:$C$1048576,A11) -> 0 | F11: =SUMIFS($E$20:$E$1048576,$D$20:$D$1048576,$F$4,$C$20:$C$1048576,B11) -> 0 | G11: =SUMIFS($E$20:$E$1048576,$D$20:$D$1048576,$G$4,$C$20:$C$1048576,A11) -> 0 | H11: =SUMIFS($E$20:$E$1048576,$D$20:$D$1048576,$H$4,$C$20:$C$1048576,A11) -> 0 | I11: =SUM(D11:H11) -> 0 | J11: =SUMIFS($E$20:$E$1048576,$D$20:$D$1048576,$J$4,$C$20:$C$1048576,A11) -> 0 | K11: =SUMIFS($E$20:$E$1048576,$D$20:$D$1048576,$K$4,$C$20:$C$1048576,A11) -> 0 | L11: =SUMIFS($E$20:$E$1048576,$D$20:$D$1048576,$L$4,$C$20:$C$1048576,A11) -> 0 | M11: =SUMIFS($E$20:$E$1048576,$D$20:$D$1048576,$M$4,$C$20:$C$1048576,A11) -> 140 | N11: =SUM(J11:M11) -> 140 | O11: =SUM(I11-N11) -> -140
A12: Machos 13 a 24 meses | E12: =SUMIFS($E$20:$E$1048576,$D$20:$D$1048576,$E$4,$C$20:$C$1048576,A12) -> 0 | F12: =SUMIFS($E$20:$E$1048576,$D$20:$D$1048576,$F$4,$C$20:$C$1048576,B12) -> 0 | G12: =SUMIFS($E$20:$E$1048576,$D$20:$D$1048576,$G$4,$C$20:$C$1048576,A12) -> 0 | H12: =SUMIFS($E$20:$E$1048576,$D$20:$D$1048576,$H$4,$C$20:$C$1048576,A12) -> 0 | I12: =SUM(D12:H12) -> 0 | J12: =SUMIFS($E$20:$E$1048576,$D$20:$D$1048576,$J$4,$C$20:$C$1048576,A12) -> 0 | K12: =SUMIFS($E$20:$E$1048576,$D$20:$D$1048576,$K$4,$C$20:$C$1048576,A12) -> 0 | L12: =SUMIFS($E$20:$E$1048576,$D$20:$D$1048576,$L$4,$C$20:$C$1048576,A12) -> 0 | M12: =SUMIFS($E$20:$E$1048576,$D$20:$D$1048576,$M$4,$C$20:$C$1048576,A12) -> 0 | N12: =SUM(J12:M12) -> 0 | O12: =SUM(I12-N12) -> 0
A13: Machos 25 a 36 meses | E13: =SUMIFS($E$20:$E$1048576,$D$20:$D$1048576,$E$4,$C$20:$C$1048576,A13) -> 0 | F13: =SUMIFS($E$20:$E$1048576,$D$20:$D$1048576,$F$4,$C$20:$C$1048576,B13) -> 0 | G13: =SUMIFS($E$20:$E$1048576,$D$20:$D$1048576,$G$4,$C$20:$C$1048576,A13) -> 0 | H13: =SUMIFS($E$20:$E$1048576,$D$20:$D$1048576,$H$4,$C$20:$C$1048576,A13) -> 0 | I13: =SUM(D13:H13) -> 0 | J13: =SUMIFS($E$20:$E$1048576,$D$20:$D$1048576,$J$4,$C$20:$C$1048576,A13) -> 0 | K13: =SUMIFS($E$20:$E$1048576,$D$20:$D$1048576,$K$4,$C$20:$C$1048576,A13) -> 0 | L13: =SUMIFS($E$20:$E$1048576,$D$20:$D$1048576,$L$4,$C$20:$C$1048576,A13) -> 0 | M13: =SUMIFS($E$20:$E$1048576,$D$20:$D$1048576,$M$4,$C$20:$C$1048576,A13) -> 0 | N13: =SUM(J13:M13) -> 0 | O13: =SUM(I13-N13) -> 0
A14: Touros | E14: =SUMIFS($E$20:$E$1048576,$D$20:$D$1048576,$E$4,$C$20:$C$1048576,A14) -> 0 | F14: =SUMIFS($E$20:$E$1048576,$D$20:$D$1048576,$F$4,$C$20:$C$1048576,B14) -> 0 | G14: =SUMIFS($E$20:$E$1048576,$D$20:$D$1048576,$G$4,$C$20:$C$1048576,A14) -> 0 | H14: =SUMIFS($E$20:$E$1048576,$D$20:$D$1048576,$H$4,$C$20:$C$1048576,A14) -> 0 | I14: =SUM(D14:H14) -> 0 | J14: =SUMIFS($E$20:$E$1048576,$D$20:$D$1048576,$J$4,$C$20:$C$1048576,A14) -> 0 | K14: =SUMIFS($E$20:$E$1048576,$D$20:$D$1048576,$K$4,$C$20:$C$1048576,A14) -> 0 | L14: =SUMIFS($E$20:$E$1048576,$D$20:$D$1048576,$L$4,$C$20:$C$1048576,A14) -> 0 | M14: =SUMIFS($E$20:$E$1048576,$D$20:$D$1048576,$M$4,$C$20:$C$1048576,A14) -> 0 | N14: =SUM(J14:M14) -> 0 | O14: =SUM(I14-N14) -> 0
A15: TROPA | E15: =SUMIFS($E$20:$E$1048576,$D$20:$D$1048576,$E$4,$C$20:$C$1048576,A15) -> 0 | G15: =SUMIFS($E$20:$E$1048576,$D$20:$D$1048576,$G$4,$C$20:$C$1048576,A15) -> 0 | H15: =SUMIFS($E$20:$E$1048576,$D$20:$D$1048576,$H$4,$C$20:$C$1048576,A15) -> 0 | I15: =SUM(D15:H15) -> 0 | J15: =SUMIFS($E$20:$E$1048576,$D$20:$D$1048576,$J$4,$C$20:$C$1048576,A15) -> 0 | K15: =SUMIFS($E$20:$E$1048576,$D$20:$D$1048576,$K$4,$C$20:$C$1048576,A15) -> 0 | L15: =SUMIFS($E$20:$E$1048576,$D$20:$D$1048576,$L$4,$C$20:$C$1048576,A15) -> 0 | M15: =SUMIFS($E$20:$E$1048576,$D$20:$D$1048576,$M$4,$C$20:$C$1048576,A15) -> 0 | N15: =SUM(J15:M15) -> 0 | O15: =SUM(I15-N15) -> 0
A16: TOTAL | D16: =SUM(D5:D15) -> 0 | E16: =SUM(E5:E15) -> 0 | F16: =SUM(F5:F15) -> 0 | G16: =SUM(G5:G15) -> 0 | H16: =SUM(H5:H15) -> 0 | I16: =SUM(I5:I15) -> 0 | J16: =SUM(J5:J15) -> 0 | K16: =SUM(K5:K15) -> 0 | ... O16: =SUM(O5:O15) -> -140
A18: MOVIMENTAÇÕES DE BOVINOS
A19: DATA | B19: MÊS | C19: CATEGORIA | D19: TIPO | E19: QUANTIDADE | F19: SAIDA | G19: DESTINO | H19: PESO TOTAL | I19: PESO MÉDIO
A20: 45858 | B20: =TEXT(Tabela22[[#This Row],[DATA]],"mmm") -> jul | C20: Machos Desm. até 12m | D20: TRANSF. S | E20: 95 | F20: - | G20: GOIANO | H20: - | I20: =Tabela22[[#This Row],[PESO TOTAL]]/Tabela22[[#This Row],[QUANTIDADE]] -> #VALUE!
A21: 45889 | B21: =TEXT(Tabela22[[#This Row],[DATA]],"mmm") -> ago | C21: Machos Desm. até 12m | D21: TRANSF. S | E21: 45 | G21: GOIANO | I21: =Tabela22[[#This Row],[PESO TOTAL]]/Tabela22[[#This Row],[QUANTIDADE]] -> 0
B22: =TEXT(Tabela22[[#This Row],[DATA]],"mmm") -> jan | I22: =Tabela22[[#This Row],[PESO TOTAL]]/Tabela22[[#This Row],[QUANTIDADE]] -> #DIV/0!
B23: =TEXT(Tabela22[[#This Row],[DATA]],"mmm") -> jan | I23: =Tabela22[[#This Row],[PESO TOTAL]]/Tabela22[[#This Row],[QUANTIDADE]] -> #DIV/0!
B24: =TEXT(Tabela22[[#This Row],[DATA]],"mmm") -> jan | I24: =Tabela22[[#This Row],[PESO TOTAL]]/Tabela22[[#This Row],[QUANTIDADE]] -> #DIV/0!
B25: =TEXT(Tabela22[[#This Row],[DATA]],"mmm") -> jan | I25: =Tabela22[[#This Row],[PESO TOTAL]]/Tabela22[[#This Row],[QUANTIDADE]] -> #DIV/0!
B26: =TEXT(Tabela22[[#This Row],[DATA]],"mmm") -> jan | I26: =Tabela22[[#This Row],[PESO TOTAL]]/Tabela22[[#This Row],[QUANTIDADE]] -> #DIV/0!
B27: =TEXT(Tabela22[[#This Row],[DATA]],"mmm") -> jan | I27: =Tabela22[[#This Row],[PESO TOTAL]]/Tabela22[[#This Row],[QUANTIDADE]] -> #DIV/0!
B28: =TEXT(Tabela22[[#This Row],[DATA]],"mmmm") -> janeiro | I28: =Tabela22[[#This Row],[PESO TOTAL]]/Tabela22[[#This Row],[QUANTIDADE]] -> #DIV/0!
B29: =TEXT(Tabela22[[#This Row],[DATA]],"mmmm") -> janeiro | I29: =Tabela22[[#This Row],[PESO TOTAL]]/Tabela22[[#This Row],[QUANTIDADE]] -> #DIV/0!
B30: =TEXT(Tabela22[[#This Row],[DATA]],"mmmm") -> janeiro | I30: =Tabela22[[#This Row],[PESO TOTAL]]/Tabela22[[#This Row],[QUANTIDADE]] -> #DIV/0!
B31: =TEXT(Tabela22[[#This Row],[DATA]],"mmmm") -> janeiro | I31: =Tabela22[[#This Row],[PESO TOTAL]]/Tabela22[[#This Row],[QUANTIDADE]] -> #DIV/0!
B32: =TEXT(Tabela22[[#This Row],[DATA]],"mmmm") -> janeiro | I32: =Tabela22[[#This Row],[PESO TOTAL]]/Tabela22[[#This Row],[QUANTIDADE]] -> #DIV/0!
B33: =TEXT(Tabela22[[#This Row],[DATA]],"mmmm") -> janeiro | I33: =Tabela22[[#This Row],[PESO TOTAL]]/Tabela22[[#This Row],[QUANTIDADE]] -> #DIV/0!
B34: =TEXT(Tabela22[[#This Row],[DATA]],"mmmm") -> janeiro | I34: =Tabela22[[#This Row],[PESO TOTAL]]/Tabela22[[#This Row],[QUANTIDADE]] -> #DIV/0!
B35: =TEXT(Tabela22[[#This Row],[DATA]],"mmmm") -> janeiro | I35: =Tabela22[[#This Row],[PESO TOTAL]]/Tabela22[[#This Row],[QUANTIDADE]] -> #DIV/0!
B36: =TEXT(Tabela22[[#This Row],[DATA]],"mmmm") -> janeiro | I36: =Tabela22[[#This Row],[PESO TOTAL]]/Tabela22[[#This Row],[QUANTIDADE]] -> #DIV/0!
B37: =TEXT(Tabela22[[#This Row],[DATA]],"mmmm") -> janeiro | I37: =Tabela22[[#This Row],[PESO TOTAL]]/Tabela22[[#This Row],[QUANTIDADE]] -> #DIV/0!
B38: =TEXT(Tabela22[[#This Row],[DATA]],"mmmm") -> janeiro | I38: =Tabela22[[#This Row],[PESO TOTAL]]/Tabela22[[#This Row],[QUANTIDADE]] -> #DIV/0!
B39: =TEXT(Tabela22[[#This Row],[DATA]],"mmmm") -> janeiro | I39: =Tabela22[[#This Row],[PESO TOTAL]]/Tabela22[[#This Row],[QUANTIDADE]] -> #DIV/0!
... B572: =TEXT(Tabela22[[#This Row],[DATA]],"mmmm") -> janeiro | I572: =Tabela22[[#This Row],[PESO TOTAL]]/Tabela22[[#This Row],[QUANTIDADE]] -> #DIV/0!

Sheet BAIXÃO
A1: MOVIMENTAÇÃO FAZENDA BAIXÃO | S1: COMPRA
D2: ENTRADAS | J2: SAIDAS | O2: POSIÇÃO | S2: NASC.
S3: TRANSF. E
A4: CATEGORIAS | D4: SALDO ANTERIOR | E4: COMPRA | F4: EVOLUÇ | G4: NASC. | H4: TRANSF. E | I4: TOTAL | J4: ABATE | K4: MORTE | L4: VENDA | M4: TRANSF. S | N4: TOTAL | O4: FINAL | S4: ABATE
A5: Femeas + 36 meses | E5: =SUMIFS($E$20:$E$1048576,$D$20:$D$1048576,$E$4,$C$20:$C$1048576,A5) -> 0 | F5: =SUMIFS($E$20:$E$1048576,$D$20:$D$1048576,$F$4,$C$20:$C$1048576,B5) -> 0 | G5: =SUMIFS($E$20:$E$1048576,$D$20:$D$1048576,$G$4,$C$20:$C$1048576,A5) -> 0 | H5: =SUMIFS($E$20:$E$1048576,$D$20:$D$1048576,$H$4,$C$20:$C$1048576,A5) -> 0 | I5: =SUM(D5:H5) -> 0 | J5: =SUMIFS($E$20:$E$1048576,$D$20:$D$1048576,$J$4,$C$20:$C$1048576,A5) -> 0 | K5: =SUMIFS($E$20:$E$1048576,$D$20:$D$1048576,$K$4,$C$20:$C$1048576,A5) -> 0 | L5: =SUMIFS($E$20:$E$1048576,$D$20:$D$1048576,$L$4,$C$20:$C$1048576,A5) -> 0 | M5: =SUMIFS($E$20:$E$1048576,$D$20:$D$1048576,$M$4,$C$20:$C$1048576,A5) -> 0 | N5: =SUM(J5:M5) -> 0 | O5: =SUM(I5-N5) -> 0 | S5: MORTE
A6: Femeas 25 a 36 meses | E6: =SUMIFS($E$20:$E$1048576,$D$20:$D$1048576,$E$4,$C$20:$C$1048576,A6) -> 0 | F6: =SUMIFS($E$20:$E$1048576,$D$20:$D$1048576,$F$4,$C$20:$C$1048576,B6) -> 0 | G6: =SUMIFS($E$20:$E$1048576,$D$20:$D$1048576,$G$4,$C$20:$C$1048576,A6) -> 0 | H6: =SUMIFS($E$20:$E$1048576,$D$20:$D$1048576,$H$4,$C$20:$C$1048576,A6) -> 0 | I6: =SUM(D6:H6) -> 0 | J6: =SUMIFS($E$20:$E$1048576,$D$20:$D$1048576,$J$4,$C$20:$C$1048576,A6) -> 0 | K6: =SUMIFS($E$20:$E$1048576,$D$20:$D$1048576,$K$4,$C$20:$C$1048576,A6) -> 0 | L6: =SUMIFS($E$20:$E$1048576,$D$20:$D$1048576,$L$4,$C$20:$C$1048576,A6) -> 0 | M6: =SUMIFS($E$20:$E$1048576,$D$20:$D$1048576,$M$4,$C$20:$C$1048576,A6) -> 0 | N6: =SUM(J6:M6) -> 0 | O6: =SUM(I6-N6) -> 0 | S6: TRANSF. S
A7: Femeas 13 a 24 meses | E7: =SUMIFS($E$20:$E$1048576,$D$20:$D$1048576,$E$4,$C$20:$C$1048576,A7) -> 0 | F7: =SUMIFS($E$20:$E$1048576,$D$20:$D$1048576,$F$4,$C$20:$C$1048576,B7) -> 0 | G7: =SUMIFS($E$20:$E$1048576,$D$20:$D$1048576,$G$4,$C$20:$C$1048576,A7) -> 0 | H7: =SUMIFS($E$20:$E$1048576,$D$20:$D$1048576,$H$4,$C$20:$C$1048576,A7) -> 0 | I7: =SUM(D7:H7) -> 0 | J7: =SUMIFS($E$20:$E$1048576,$D$20:$D$1048576,$J$4,$C$20:$C$1048576,A7) -> 0 | K7: =SUMIFS($E$20:$E$1048576,$D$20:$D$1048576,$K$4,$C$20:$C$1048576,A7) -> 0 | L7: =SUMIFS($E$20:$E$1048576,$D$20:$D$1048576,$L$4,$C$20:$C$1048576,A7) -> 0 | M7: =SUMIFS($E$20:$E$1048576,$D$20:$D$1048576,$M$4,$C$20:$C$1048576,A7) -> 0 | N7: =SUM(J7:M7) -> 0 | O7: =SUM(I7-N7) -> 0 | S7: SALDO ANTERIOR
A8: Femeas Desm. até 12m | E8: =SUMIFS($E$20:$E$1048576,$D$20:$D$1048576,$E$4,$C$20:$C$1048576,A8) -> 0 | F8: =SUMIFS($E$20:$E$1048576,$D$20:$D$1048576,$F$4,$C$20:$C$1048576,B8) -> 0 | G8: =SUMIFS($E$20:$E$1048576,$D$20:$D$1048576,$G$4,$C$20:$C$1048576,A8) -> 0 | H8: =SUMIFS($E$20:$E$1048576,$D$20:$D$1048576,$H$4,$C$20:$C$1048576,A8) -> 0 | I8: =SUM(D8:H8) -> 0 | J8: =SUMIFS($E$20:$E$1048576,$D$20:$D$1048576,$J$4,$C$20:$C$1048576,A8) -> 0 | K8: =SUMIFS($E$20:$E$1048576,$D$20:$D$1048576,$K$4,$C$20:$C$1048576,A8) -> 0 | L8: =SUMIFS($E$20:$E$1048576,$D$20:$D$1048576,$L$4,$C$20:$C$1048576,A8) -> 0 | M8: =SUMIFS($E$20:$E$1048576,$D$20:$D$1048576,$M$4,$C$20:$C$1048576,A8) -> 0 | N8: =SUM(J8:M8) -> 0 | O8: =SUM(I8-N8) -> 0 | S8: EVOLUÇ
A9: Bezerras Mamando | E9: =SUMIFS($E$20:$E$1048576,$D$20:$D$1048576,$E$4,$C$20:$C$1048576,A9) -> 0 | F9: =SUMIFS($E$20:$E$1048576,$D$20:$D$1048576,$F$4,$C$20:$C$1048576,B9) -> 0 | G9: =SUMIFS($E$20:$E$1048576,$D$20:$D$1048576,$G$4,$C$20:$C$1048576,A9) -> 0 | H9: =SUMIFS($E$20:$E$1048576,$D$20:$D$1048576,$H$4,$C$20:$C$1048576,A9) -> 0 | I9: =SUM(D9:H9) -> 0 | J9: =SUMIFS($E$20:$E$1048576,$D$20:$D$1048576,$J$4,$C$20:$C$1048576,A9) -> 0 | K9: =SUMIFS($E$20:$E$1048576,$D$20:$D$1048576,$K$4,$C$20:$C$1048576,A9) -> 0 | L9: =SUMIFS($E$20:$E$1048576,$D$20:$D$1048576,$L$4,$C$20:$C$1048576,A9) -> 0 | M9: =SUMIFS($E$20:$E$1048576,$D$20:$D$1048576,$M$4,$C$20:$C$1048576,A9) -> 0 | N9: =SUM(J9:M9) -> 0 | O9: =SUM(I9-N9) -> 0 | S9: VENDA
A10: Bezerros Mamando | E10: =SUMIFS($E$20:$E$1048576,$D$20:$D$1048576,$E$4,$C$20:$C$1048576,A10) -> 0 | F10: =SUMIFS($E$20:$E$1048576,$D$20:$D$1048576,$F$4,$C$20:$C$1048576,B10) -> 0 | G10: =SUMIFS($E$20:$E$1048576,$D$20:$D$1048576,$G$4,$C$20:$C$1048576,A10) -> 0 | H10: =SUMIFS($E$20:$E$1048576,$D$20:$D$1048576,$H$4,$C$20:$C$1048576,A10) -> 0 | I10: =SUM(D10:H10) -> 0 | J10: =SUMIFS($E$20:$E$1048576,$D$20:$D$1048576,$J$4,$C$20:$C$1048576,A10) -> 0 | K10: =SUMIFS($E$20:$E$1048576,$D$20:$D$1048576,$K$4,$C$20:$C$1048576,A10) -> 0 | L10: =SUMIFS($E$20:$E$1048576,$D$20:$D$1048576,$L$4,$C$20:$C$1048576,A10) -> 0 | M10: =SUMIFS($E$20:$E$1048576,$D$20:$D$1048576,$M$4,$C$20:$C$1048576,A10) -> 0 | N10: =SUM(J10:M10) -> 0 | O10: =SUM(I10-N10) -> 0
A11: Machos Desm. até 12m | E11: =SUMIFS($E$20:$E$1048576,$D$20:$D$1048576,$E$4,$C$20:$C$1048576,A11) -> 0 | F11: =SUMIFS($E$20:$E$1048576,$D$20:$D$1048576,$F$4,$C$20:$C$1048576,B11) -> 0 | G11: =SUMIFS($E$20:$E$1048576,$D$20:$D$1048576,$G$4,$C$20:$C$1048576,A11) -> 0 | H11: =SUMIFS($E$20:$E$1048576,$D$20:$D$1048576,$H$4,$C$20:$C$1048576,A11) -> 0 | I11: =SUM(D11:H11) -> 0 | J11: =SUMIFS($E$20:$E$1048576,$D$20:$D$1048576,$J$4,$C$20:$C$1048576,A11) -> 0 | K11: =SUMIFS($E$20:$E$1048576,$D$20:$D$1048576,$K$4,$C$20:$C$1048576,A11) -> 0 | L11: =SUMIFS($E$20:$E$1048576,$D$20:$D$1048576,$L$4,$C$20:$C$1048576,A11) -> 0 | M11: =SUMIFS($E$20:$E$1048576,$D$20:$D$1048576,$M$4,$C$20:$C$1048576,A11) -> 0 | N11: =SUM(J11:M11) -> 0 | O11: =SUM(I11-N11) -> 0
A12: Machos 13 a 24 meses | E12: =SUMIFS($E$20:$E$1048576,$D$20:$D$1048576,$E$4,$C$20:$C$1048576,A12) -> 0 | F12: =SUMIFS($E$20:$E$1048576,$D$20:$D$1048576,$F$4,$C$20:$C$1048576,B12) -> 0 | G12: =SUMIFS($E$20:$E$1048576,$D$20:$D$1048576,$G$4,$C$20:$C$1048576,A12) -> 0 | H12: =SUMIFS($E$20:$E$1048576,$D$20:$D$1048576,$H$4,$C$20:$C$1048576,A12) -> 0 | I12: =SUM(D12:H12) -> 0 | J12: =SUMIFS($E$20:$E$1048576,$D$20:$D$1048576,$J$4,$C$20:$C$1048576,A12) -> 0 | K12: =SUMIFS($E$20:$E$1048576,$D$20:$D$1048576,$K$4,$C$20:$C$1048576,A12) -> 0 | L12: =SUMIFS($E$20:$E$1048576,$D$20:$D$1048576,$L$4,$C$20:$C$1048576,A12) -> 0 | M12: =SUMIFS($E$20:$E$1048576,$D$20:$D$1048576,$M$4,$C$20:$C$1048576,A12) -> 0 | N12: =SUM(J12:M12) -> 0 | O12: =SUM(I12-N12) -> 0
A13: Machos 25 a 36 meses | E13: =SUMIFS($E$20:$E$1048576,$D$20:$D$1048576,$E$4,$C$20:$C$1048576,A13) -> 0 | F13: =SUMIFS($E$20:$E$1048576,$D$20:$D$1048576,$F$4,$C$20:$C$1048576,B13) -> 0 | G13: =SUMIFS($E$20:$E$1048576,$D$20:$D$1048576,$G$4,$C$20:$C$1048576,A13) -> 0 | H13: =SUMIFS($E$20:$E$1048576,$D$20:$D$1048576,$H$4,$C$20:$C$1048576,A13) -> 0 | I13: =SUM(D13:H13) -> 0 | J13: =SUMIFS($E$20:$E$1048576,$D$20:$D$1048576,$J$4,$C$20:$C$1048576,A13) -> 0 | K13: =SUMIFS($E$20:$E$1048576,$D$20:$D$1048576,$K$4,$C$20:$C$1048576,A13) -> 0 | L13: =SUMIFS($E$20:$E$1048576,$D$20:$D$1048576,$L$4,$C$20:$C$1048576,A13) -> 0 | M13: =SUMIFS($E$20:$E$1048576,$D$20:$D$1048576,$M$4,$C$20:$C$1048576,A13) -> 0 | N13: =SUM(J13:M13) -> 0 | O13: =SUM(I13-N13) -> 0
A14: Touros | E14: =SUMIFS($E$20:$E$1048576,$D$20:$D$1048576,$E$4,$C$20:$C$1048576,A14) -> 0 | F14: =SUMIFS($E$20:$E$1048576,$D$20:$D$1048576,$F$4,$C$20:$C$1048576,B14) -> 0 | G14: =SUMIFS($E$20:$E$1048576,$D$20:$D$1048576,$G$4,$C$20:$C$1048576,A14) -> 0 | H14: =SUMIFS($E$20:$E$1048576,$D$20:$D$1048576,$H$4,$C$20:$C$1048576,A14) -> 0 | I14: =SUM(D14:H14) -> 0 | J14: =SUMIFS($E$20:$E$1048576,$D$20:$D$1048576,$J$4,$C$20:$C$1048576,A14) -> 0 | K14: =SUMIFS($E$20:$E$1048576,$D$20:$D$1048576,$K$4,$C$20:$C$1048576,A14) -> 0 | L14: =SUMIFS($E$20:$E$1048576,$D$20:$D$1048576,$L$4,$C$20:$C$1048576,A14) -> 0 | M14: =SUMIFS($E$20:$E$1048576,$D$20:$D$1048576,$M$4,$C$20:$C$1048576,A14) -> 0 | N14: =SUM(J14:M14) -> 0 | O14: =SUM(I14-N14) -> 0
A15: TROPA | E15: =SUMIFS($E$20:$E$1048576,$D$20:$D$1048576,$E$4,$C$20:$C$1048576,A15) -> 0 | F15: 0 | G15: =SUMIFS($E$20:$E$1048576,$D$20:$D$1048576,$G$4,$C$20:$C$1048576,A15) -> 0 | H15: =SUMIFS($E$20:$E$1048576,$D$20:$D$1048576,$H$4,$C$20:$C$1048576,A15) -> 0 | I15: =SUM(D15:H15) -> 0 | J15: =SUMIFS($E$20:$E$1048576,$D$20:$D$1048576,$J$4,$C$20:$C$1048576,A15) -> 0 | K15: =SUMIFS($E$20:$E$1048576,$D$20:$D$1048576,$K$4,$C$20:$C$1048576,A15) -> 0 | L15: =SUMIFS($E$20:$E$1048576,$D$20:$D$1048576,$L$4,$C$20:$C$1048576,A15) -> 0 | M15: =SUMIFS($E$20:$E$1048576,$D$20:$D$1048576,$M$4,$C$20:$C$1048576,A15) -> 0 | N15: =SUM(J15:M15) -> 0 | O15: =SUM(I15-N15) -> 0
A16: TOTAL | D16: =SUM(D5:D15) -> 0 | E16: =SUM(E5:E15) -> 0 | F16: =SUM(F5:F15) -> 0 | G16: =SUM(G5:G15) -> 0 | H16: =SUM(H5:H15) -> 0 | I16: =SUM(I5:I15) -> 0 | J16: =SUM(J5:J15) -> 0 | K16: =SUM(K5:K15) -> 0 | ... O16: =SUM(O5:O15) -> 0
A18: MOVIMENTAÇÕES DE BOVINOS
A19: DATA | B19: MÊS | C19: CATEGORIA | D19: TIPO | E19: QUANTIDADE | F19: SAIDA | G19: DESTINO | H19: PESO TOTAL | I19: PESO MÉDIO
B20: =TEXT(Tabela223[[#This Row],[DATA]],"mmm") -> jan | I20: =Tabela22[[#This Row],[PESO TOTAL]]/Tabela22[[#This Row],[QUANTIDADE]] -> #VALUE!
B21: =TEXT(Tabela223[[#This Row],[DATA]],"mmm") -> jan | I21: =Tabela22[[#This Row],[PESO TOTAL]]/Tabela22[[#This Row],[QUANTIDADE]] -> 0
B22: =TEXT(Tabela223[[#This Row],[DATA]],"mmm") -> jan | I22: =Tabela22[[#This Row],[PESO TOTAL]]/Tabela22[[#This Row],[QUANTIDADE]] -> #DIV/0!
B23: =TEXT(Tabela223[[#This Row],[DATA]],"mmm") -> jan | I23: =Tabela22[[#This Row],[PESO TOTAL]]/Tabela22[[#This Row],[QUANTIDADE]] -> #DIV/0!
B24: =TEXT(Tabela223[[#This Row],[DATA]],"mmm") -> jan | I24: =Tabela22[[#This Row],[PESO TOTAL]]/Tabela22[[#This Row],[QUANTIDADE]] -> #DIV/0!
B25: =TEXT(Tabela223[[#This Row],[DATA]],"mmm") -> jan | I25: =Tabela22[[#This Row],[PESO TOTAL]]/Tabela22[[#This Row],[QUANTIDADE]] -> #DIV/0!
B26: =TEXT(Tabela223[[#This Row],[DATA]],"mmm") -> jan | I26: =Tabela22[[#This Row],[PESO TOTAL]]/Tabela22[[#This Row],[QUANTIDADE]] -> #DIV/0!
B27: =TEXT(Tabela223[[#This Row],[DATA]],"mmm") -> jan | I27: =Tabela22[[#This Row],[PESO TOTAL]]/Tabela22[[#This Row],[QUANTIDADE]] -> #DIV/0!
B28: =TEXT(Tabela223[[#This Row],[DATA]],"mmmm") -> janeiro | I28: =Tabela22[[#This Row],[PESO TOTAL]]/Tabela22[[#This Row],[QUANTIDADE]] -> #DIV/0!
B29: =TEXT(Tabela223[[#This Row],[DATA]],"mmmm") -> janeiro | I29: =Tabela22[[#This Row],[PESO TOTAL]]/Tabela22[[#This Row],[QUANTIDADE]] -> #DIV/0!
B30: =TEXT(Tabela223[[#This Row],[DATA]],"mmmm") -> janeiro | I30: =Tabela22[[#This Row],[PESO TOTAL]]/Tabela22[[#This Row],[QUANTIDADE]] -> #DIV/0!
B31: =TEXT(Tabela223[[#This Row],[DATA]],"mmmm") -> janeiro | I31: =Tabela22[[#This Row],[PESO TOTAL]]/Tabela22[[#This Row],[QUANTIDADE]] -> #DIV/0!
B32: =TEXT(Tabela223[[#This Row],[DATA]],"mmmm") -> janeiro | I32: =Tabela22[[#This Row],[PESO TOTAL]]/Tabela22[[#This Row],[QUANTIDADE]] -> #DIV/0!
B33: =TEXT(Tabela223[[#This Row],[DATA]],"mmmm") -> janeiro | I33: =Tabela22[[#This Row],[PESO TOTAL]]/Tabela22[[#This Row],[QUANTIDADE]] -> #DIV/0!
B34: =TEXT(Tabela223[[#This Row],[DATA]],"mmmm") -> janeiro | I34: =Tabela22[[#This Row],[PESO TOTAL]]/Tabela22[[#This Row],[QUANTIDADE]] -> #DIV/0!
B35: =TEXT(Tabela223[[#This Row],[DATA]],"mmmm") -> janeiro | I35: =Tabela22[[#This Row],[PESO TOTAL]]/Tabela22[[#This Row],[QUANTIDADE]] -> #DIV/0!
B36: =TEXT(Tabela223[[#This Row],[DATA]],"mmmm") -> janeiro | I36: =Tabela22[[#This Row],[PESO TOTAL]]/Tabela22[[#This Row],[QUANTIDADE]] -> #DIV/0!
B37: =TEXT(Tabela223[[#This Row],[DATA]],"mmmm") -> janeiro | I37: =Tabela22[[#This Row],[PESO TOTAL]]/Tabela22[[#This Row],[QUANTIDADE]] -> #DIV/0!
B38: =TEXT(Tabela223[[#This Row],[DATA]],"mmmm") -> janeiro | I38: =Tabela22[[#This Row],[PESO TOTAL]]/Tabela22[[#This Row],[QUANTIDADE]] -> #DIV/0!
B39: =TEXT(Tabela223[[#This Row],[DATA]],"mmmm") -> janeiro | I39: =Tabela22[[#This Row],[PESO TOTAL]]/Tabela22[[#This Row],[QUANTIDADE]] -> #DIV/0!
... B572: =TEXT(Tabela223[[#This Row],[DATA]],"mmmm") -> janeiro | I572: =Tabela22[[#This Row],[PESO TOTAL]]/Tabela22[[#This Row],[QUANTIDADE]] -> #DIV/0!

Sheet MORADA DO BOI
A1: MOVIMENTAÇÃO FAZENDA MORADA DO BOI | S1: COMPRA
D2: ENTRADAS | J2: SAIDAS | O2: POSIÇÃO | S2: NASC.
S3: TRANSF. E
A4: CATEGORIAS | D4: SALDO ANTERIOR | E4: COMPRA | F4: EVOLUÇ | G4: NASC. | H4: TRANSF. E | I4: TOTAL | J4: ABATE | K4: MORTE | L4: VENDA | M4: TRANSF. S | N4: TOTAL | O4: FINAL | S4: ABATE
A5: Femeas + 36 meses | E5: =SUMIFS($E$20:$E$1048576,$D$20:$D$1048576,$E$4,$C$20:$C$1048576,A5) -> 0 | F5: =SUMIFS($E$20:$E$1048576,$D$20:$D$1048576,$F$4,$C$20:$C$1048576,B5) -> 0 | G5: =SUMIFS($E$20:$E$1048576,$D$20:$D$1048576,$G$4,$C$20:$C$1048576,A5) -> 0 | H5: =SUMIFS($E$20:$E$1048576,$D$20:$D$1048576,$H$4,$C$20:$C$1048576,A5) -> 0 | I5: =SUM(D5:H5) -> 0 | J5: =SUMIFS($E$20:$E$1048576,$D$20:$D$1048576,$J$4,$C$20:$C$1048576,A5) -> 0 | K5: =SUMIFS($E$20:$E$1048576,$D$20:$D$1048576,$K$4,$C$20:$C$1048576,A5) -> 0 | L5: =SUMIFS($E$20:$E$1048576,$D$20:$D$1048576,$L$4,$C$20:$C$1048576,A5) -> 0 | M5: =SUMIFS($E$20:$E$1048576,$D$20:$D$1048576,$M$4,$C$20:$C$1048576,A5) -> 0 | N5: =SUM(J5:M5) -> 0 | O5: =SUM(I5-N5) -> 0 | S5: MORTE
A6: Femeas 25 a 36 meses | E6: =SUMIFS($E$20:$E$1048576,$D$20:$D$1048576,$E$4,$C$20:$C$1048576,A6) -> 0 | F6: =SUMIFS($E$20:$E$1048576,$D$20:$D$1048576,$F$4,$C$20:$C$1048576,B6) -> 0 | G6: =SUMIFS($E$20:$E$1048576,$D$20:$D$1048576,$G$4,$C$20:$C$1048576,A6) -> 0 | H6: =SUMIFS($E$20:$E$1048576,$D$20:$D$1048576,$H$4,$C$20:$C$1048576,A6) -> 0 | I6: =SUM(D6:H6) -> 0 | J6: =SUMIFS($E$20:$E$1048576,$D$20:$D$1048576,$J$4,$C$20:$C$1048576,A6) -> 0 | K6: =SUMIFS($E$20:$E$1048576,$D$20:$D$1048576,$K$4,$C$20:$C$1048576,A6) -> 0 | L6: =SUMIFS($E$20:$E$1048576,$D$20:$D$1048576,$L$4,$C$20:$C$1048576,A6) -> 0 | M6: =SUMIFS($E$20:$E$1048576,$D$20:$D$1048576,$M$4,$C$20:$C$1048576,A6) -> 0 | N6: =SUM(J6:M6) -> 0 | O6: =SUM(I6-N6) -> 0 | S6: TRANSF. S
A7: Femeas 13 a 24 meses | E7: =SUMIFS($E$20:$E$1048576,$D$20:$D$1048576,$E$4,$C$20:$C$1048576,A7) -> 0 | F7: =SUMIFS($E$20:$E$1048576,$D$20:$D$1048576,$F$4,$C$20:$C$1048576,B7) -> 0 | G7: =SUMIFS($E$20:$E$1048576,$D$20:$D$1048576,$G$4,$C$20:$C$1048576,A7) -> 0 | H7: =SUMIFS($E$20:$E$1048576,$D$20:$D$1048576,$H$4,$C$20:$C$1048576,A7) -> 0 | I7: =SUM(D7:H7) -> 0 | J7: =SUMIFS($E$20:$E$1048576,$D$20:$D$1048576,$J$4,$C$20:$C$1048576,A7) -> 0 | K7: =SUMIFS($E$20:$E$1048576,$D$20:$D$1048576,$K$4,$C$20:$C$1048576,A7) -> 0 | L7: =SUMIFS($E$20:$E$1048576,$D$20:$D$1048576,$L$4,$C$20:$C$1048576,A7) -> 0 | M7: =SUMIFS($E$20:$E$1048576,$D$20:$D$1048576,$M$4,$C$20:$C$1048576,A7) -> 0 | N7: =SUM(J7:M7) -> 0 | O7: =SUM(I7-N7) -> 0 | S7: SALDO ANTERIOR
A8: Femeas Desm. até 12m | E8: =SUMIFS($E$20:$E$1048576,$D$20:$D$1048576,$E$4,$C$20:$C$1048576,A8) -> 0 | F8: =SUMIFS($E$20:$E$1048576,$D$20:$D$1048576,$F$4,$C$20:$C$1048576,B8) -> 0 | G8: =SUMIFS($E$20:$E$1048576,$D$20:$D$1048576,$G$4,$C$20:$C$1048576,A8) -> 0 | H8: =SUMIFS($E$20:$E$1048576,$D$20:$D$1048576,$H$4,$C$20:$C$1048576,A8) -> 0 | I8: =SUM(D8:H8) -> 0 | J8: =SUMIFS($E$20:$E$1048576,$D$20:$D$1048576,$J$4,$C$20:$C$1048576,A8) -> 0 | K8: =SUMIFS($E$20:$E$1048576,$D$20:$D$1048576,$K$4,$C$20:$C$1048576,A8) -> 0 | L8: =SUMIFS($E$20:$E$1048576,$D$20:$D$1048576,$L$4,$C$20:$C$1048576,A8) -> 0 | M8: =SUMIFS($E$20:$E$1048576,$D$20:$D$1048576,$M$4,$C$20:$C$1048576,A8) -> 0 | N8: =SUM(J8:M8) -> 0 | O8: =SUM(I8-N8) -> 0 | S8: EVOLUÇ
A9: Bezerras Mamando | E9: =SUMIFS($E$20:$E$1048576,$D$20:$D$1048576,$E$4,$C$20:$C$1048576,A9) -> 0 | F9: =SUMIFS($E$20:$E$1048576,$D$20:$D$1048576,$F$4,$C$20:$C$1048576,B9) -> 0 | G9: =SUMIFS($E$20:$E$1048576,$D$20:$D$1048576,$G$4,$C$20:$C$1048576,A9) -> 0 | H9: =SUMIFS($E$20:$E$1048576,$D$20:$D$1048576,$H$4,$C$20:$C$1048576,A9) -> 0 | I9: =SUM(D9:H9) -> 0 | J9: =SUMIFS($E$20:$E$1048576,$D$20:$D$1048576,$J$4,$C$20:$C$1048576,A9) -> 0 | K9: =SUMIFS($E$20:$E$1048576,$D$20:$D$1048576,$K$4,$C$20:$C$1048576,A9) -> 0 | L9: =SUMIFS($E$20:$E$1048576,$D$20:$D$1048576,$L$4,$C$20:$C$1048576,A9) -> 0 | M9: =SUMIFS($E$20:$E$1048576,$D$20:$D$1048576,$M$4,$C$20:$C$1048576,A9) -> 0 | N9: =SUM(J9:M9) -> 0 | O9: =SUM(I9-N9) -> 0 | S9: VENDA
A10: Bezerros Mamando | E10: =SUMIFS($E$20:$E$1048576,$D$20:$D$1048576,$E$4,$C$20:$C$1048576,A10) -> 0 | F10: =SUMIFS($E$20:$E$1048576,$D$20:$D$1048576,$F$4,$C$20:$C$1048576,B10) -> 0 | G10: =SUMIFS($E$20:$E$1048576,$D$20:$D$1048576,$G$4,$C$20:$C$1048576,A10) -> 0 | H10: =SUMIFS($E$20:$E$1048576,$D$20:$D$1048576,$H$4,$C$20:$C$1048576,A10) -> 0 | I10: =SUM(D10:H10) -> 0 | J10: =SUMIFS($E$20:$E$1048576,$D$20:$D$1048576,$J$4,$C$20:$C$1048576,A10) -> 0 | K10: =SUMIFS($E$20:$E$1048576,$D$20:$D$1048576,$K$4,$C$20:$C$1048576,A10) -> 0 | L10: =SUMIFS($E$20:$E$1048576,$D$20:$D$1048576,$L$4,$C$20:$C$1048576,A10) -> 0 | M10: =SUMIFS($E$20:$E$1048576,$D$20:$D$1048576,$M$4,$C$20:$C$1048576,A10) -> 0 | N10: =SUM(J10:M10) -> 0 | O10: =SUM(I10-N10) -> 0
A11: Machos Desm. até 12m | E11: =SUMIFS($E$20:$E$1048576,$D$20:$D$1048576,$E$4,$C$20:$C$1048576,A11) -> 0 | F11: =SUMIFS($E$20:$E$1048576,$D$20:$D$1048576,$F$4,$C$20:$C$1048576,B11) -> 0 | G11: =SUMIFS($E$20:$E$1048576,$D$20:$D$1048576,$G$4,$C$20:$C$1048576,A11) -> 0 | H11: =SUMIFS($E$20:$E$1048576,$D$20:$D$1048576,$H$4,$C$20:$C$1048576,A11) -> 0 | I11: =SUM(D11:H11) -> 0 | J11: =SUMIFS($E$20:$E$1048576,$D$20:$D$1048576,$J$4,$C$20:$C$1048576,A11) -> 0 | K11: =SUMIFS($E$20:$E$1048576,$D$20:$D$1048576,$K$4,$C$20:$C$1048576,A11) -> 0 | L11: =SUMIFS($E$20:$E$1048576,$D$20:$D$1048576,$L$4,$C$20:$C$1048576,A11) -> 0 | M11: =SUMIFS($E$20:$E$1048576,$D$20:$D$1048576,$M$4,$C$20:$C$1048576,A11) -> 0 | N11: =SUM(J11:M11) -> 0 | O11: =SUM(I11-N11) -> 0
A12: Machos 13 a 24 meses | E12: =SUMIFS($E$20:$E$1048576,$D$20:$D$1048576,$E$4,$C$20:$C$1048576,A12) -> 0 | F12: =SUMIFS($E$20:$E$1048576,$D$20:$D$1048576,$F$4,$C$20:$C$1048576,B12) -> 0 | G12: =SUMIFS($E$20:$E$1048576,$D$20:$D$1048576,$G$4,$C$20:$C$1048576,A12) -> 0 | H12: =SUMIFS($E$20:$E$1048576,$D$20:$D$1048576,$H$4,$C$20:$C$1048576,A12) -> 0 | I12: =SUM(D12:H12) -> 0 | J12: =SUMIFS($E$20:$E$1048576,$D$20:$D$1048576,$J$4,$C$20:$C$1048576,A12) -> 0 | K12: =SUMIFS($E$20:$E$1048576,$D$20:$D$1048576,$K$4,$C$20:$C$1048576,A12) -> 0 | L12: =SUMIFS($E$20:$E$1048576,$D$20:$D$1048576,$L$4,$C$20:$C$1048576,A12) -> 0 | M12: =SUMIFS($E$20:$E$1048576,$D$20:$D$1048576,$M$4,$C$20:$C$1048576,A12) -> 0 | N12: =SUM(J12:M12) -> 0 | O12: =SUM(I12-N12) -> 0
A13: Machos 25 a 36 meses | E13: =SUMIFS($E$20:$E$1048576,$D$20:$D$1048576,$E$4,$C$20:$C$1048576,A13) -> 0 | F13: =SUMIFS($E$20:$E$1048576,$D$20:$D$1048576,$F$4,$C$20:$C$1048576,B13) -> 0 | G13: =SUMIFS($E$20:$E$1048576,$D$20:$D$1048576,$G$4,$C$20:$C$1048576,A13) -> 0 | H13: =SUMIFS($E$20:$E$1048576,$D$20:$D$1048576,$H$4,$C$20:$C$1048576,A13) -> 0 | I13: =SUM(D13:H13) -> 0 | J13: =SUMIFS($E$20:$E$1048576,$D$20:$D$1048576,$J$4,$C$20:$C$1048576,A13) -> 0 | K13: =SUMIFS($E$20:$E$1048576,$D$20:$D$1048576,$K$4,$C$20:$C$1048576,A13) -> 0 | L13: =SUMIFS($E$20:$E$1048576,$D$20:$D$1048576,$L$4,$C$20:$C$1048576,A13) -> 0 | M13: =SUMIFS($E$20:$E$1048576,$D$20:$D$1048576,$M$4,$C$20:$C$1048576,A13) -> 0 | N13: =SUM(J13:M13) -> 0 | O13: =SUM(I13-N13) -> 0
A14: Touros | E14: =SUMIFS($E$20:$E$1048576,$D$20:$D$1048576,$E$4,$C$20:$C$1048576,A14) -> 0 | F14: =SUMIFS($E$20:$E$1048576,$D$20:$D$1048576,$F$4,$C$20:$C$1048576,B14) -> 0 | G14: =SUMIFS($E$20:$E$1048576,$D$20:$D$1048576,$G$4,$C$20:$C$1048576,A14) -> 0 | H14: =SUMIFS($E$20:$E$1048576,$D$20:$D$1048576,$H$4,$C$20:$C$1048576,A14) -> 0 | I14: =SUM(D14:H14) -> 0 | J14: =SUMIFS($E$20:$E$1048576,$D$20:$D$1048576,$J$4,$C$20:$C$1048576,A14) -> 0 | K14: =SUMIFS($E$20:$E$1048576,$D$20:$D$1048576,$K$4,$C$20:$C$1048576,A14) -> 0 | L14: =SUMIFS($E$20:$E$1048576,$D$20:$D$1048576,$L$4,$C$20:$C$1048576,A14) -> 0 | M14: =SUMIFS($E$20:$E$1048576,$D$20:$D$1048576,$M$4,$C$20:$C$1048576,A14) -> 0 | N14: =SUM(J14:M14) -> 0 | O14: =SUM(I14-N14) -> 0
A15: TROPA | E15: =SUMIFS($E$20:$E$1048576,$D$20:$D$1048576,$E$4,$C$20:$C$1048576,A15) -> 0 | F15: 0 | G15: =SUMIFS($E$20:$E$1048576,$D$20:$D$1048576,$G$4,$C$20:$C$1048576,A15) -> 0 | H15: =SUMIFS($E$20:$E$1048576,$D$20:$D$1048576,$H$4,$C$20:$C$1048576,A15) -> 0 | I15: =SUM(D15:H15) -> 0 | J15: =SUMIFS($E$20:$E$1048576,$D$20:$D$1048576,$J$4,$C$20:$C$1048576,A15) -> 0 | K15: =SUMIFS($E$20:$E$1048576,$D$20:$D$1048576,$K$4,$C$20:$C$1048576,A15) -> 0 | L15: =SUMIFS($E$20:$E$1048576,$D$20:$D$1048576,$L$4,$C$20:$C$1048576,A15) -> 0 | M15: =SUMIFS($E$20:$E$1048576,$D$20:$D$1048576,$M$4,$C$20:$C$1048576,A15) -> 0 | N15: =SUM(J15:M15) -> 0 | O15: =SUM(I15-N15) -> 0
A16: TOTAL | D16: =SUM(D5:D15) -> 0 | E16: =SUM(E5:E15) -> 0 | F16: =SUM(F5:F15) -> 0 | G16: =SUM(G5:G15) -> 0 | H16: =SUM(H5:H15) -> 0 | I16: =SUM(I5:I15) -> 0 | J16: =SUM(J5:J15) -> 0 | K16: =SUM(K5:K15) -> 0 | ... O16: =SUM(O5:O15) -> 0
A18: MOVIMENTAÇÕES DE BOVINOS
A19: DATA | B19: MÊS | C19: CATEGORIA | D19: TIPO | E19: QUANTIDADE | F19: SAIDA | G19: DESTINO | H19: PESO TOTAL | I19: PESO MÉDIO
B20: =TEXT(Tabela22345[[#This Row],[DATA]],"mmm") -> jan | I20: =Tabela22[[#This Row],[PESO TOTAL]]/Tabela22[[#This Row],[QUANTIDADE]] -> #VALUE!
B21: =TEXT(Tabela22345[[#This Row],[DATA]],"mmm") -> jan | I21: =Tabela22[[#This Row],[PESO TOTAL]]/Tabela22[[#This Row],[QUANTIDADE]] -> 0
B22: =TEXT(Tabela22345[[#This Row],[DATA]],"mmm") -> jan | I22: =Tabela22[[#This Row],[PESO TOTAL]]/Tabela22[[#This Row],[QUANTIDADE]] -> #DIV/0!
B23: =TEXT(Tabela22345[[#This Row],[DATA]],"mmm") -> jan | I23: =Tabela22[[#This Row],[PESO TOTAL]]/Tabela22[[#This Row],[QUANTIDADE]] -> #DIV/0!
B24: =TEXT(Tabela22345[[#This Row],[DATA]],"mmm") -> jan | I24: =Tabela22[[#This Row],[PESO TOTAL]]/Tabela22[[#This Row],[QUANTIDADE]] -> #DIV/0!
B25: =TEXT(Tabela22345[[#This Row],[DATA]],"mmm") -> jan | I25: =Tabela22[[#This Row],[PESO TOTAL]]/Tabela22[[#This Row],[QUANTIDADE]] -> #DIV/0!
B26: =TEXT(Tabela22345[[#This Row],[DATA]],"mmm") -> jan | I26: =Tabela22[[#This Row],[PESO TOTAL]]/Tabela22[[#This Row],[QUANTIDADE]] -> #DIV/0!
B27: =TEXT(Tabela22345[[#This Row],[DATA]],"mmmm") -> janeiro | I27: =Tabela22[[#This Row],[PESO TOTAL]]/Tabela22[[#This Row],[QUANTIDADE]] -> #DIV/0!
B28: =TEXT(Tabela22345[[#This Row],[DATA]],"mmmm") -> janeiro | I28: =Tabela22[[#This Row],[PESO TOTAL]]/Tabela22[[#This Row],[QUANTIDADE]] -> #DIV/0!
B29: =TEXT(Tabela22345[[#This Row],[DATA]],"mmmm") -> janeiro | I29: =Tabela22[[#This Row],[PESO TOTAL]]/Tabela22[[#This Row],[QUANTIDADE]] -> #DIV/0!
B30: =TEXT(Tabela22345[[#This Row],[DATA]],"mmmm") -> janeiro | I30: =Tabela22[[#This Row],[PESO TOTAL]]/Tabela22[[#This Row],[QUANTIDADE]] -> #DIV/0!
B31: =TEXT(Tabela22345[[#This Row],[DATA]],"mmmm") -> janeiro | I31: =Tabela22[[#This Row],[PESO TOTAL]]/Tabela22[[#This Row],[QUANTIDADE]] -> #DIV/0!
B32: =TEXT(Tabela22345[[#This Row],[DATA]],"mmmm") -> janeiro | I32: =Tabela22[[#This Row],[PESO TOTAL]]/Tabela22[[#This Row],[QUANTIDADE]] -> #DIV/0!
B33: =TEXT(Tabela22345[[#This Row],[DATA]],"mmmm") -> janeiro | I33: =Tabela22[[#This Row],[PESO TOTAL]]/Tabela22[[#This Row],[QUANTIDADE]] -> #DIV/0!
B34: =TEXT(Tabela22345[[#This Row],[DATA]],"mmmm") -> janeiro | I34: =Tabela22[[#This Row],[PESO TOTAL]]/Tabela22[[#This Row],[QUANTIDADE]] -> #DIV/0!
B35: =TEXT(Tabela22345[[#This Row],[DATA]],"mmmm") -> janeiro | I35: =Tabela22[[#This Row],[PESO TOTAL]]/Tabela22[[#This Row],[QUANTIDADE]] -> #DIV/0!
B36: =TEXT(Tabela22345[[#This Row],[DATA]],"mmmm") -> janeiro | I36: =Tabela22[[#This Row],[PESO TOTAL]]/Tabela22[[#This Row],[QUANTIDADE]] -> #DIV/0!
B37: =TEXT(Tabela22345[[#This Row],[DATA]],"mmmm") -> janeiro | I37: =Tabela22[[#This Row],[PESO TOTAL]]/Tabela22[[#This Row],[QUANTIDADE]] -> #DIV/0!
B38: =TEXT(Tabela22345[[#This Row],[DATA]],"mmmm") -> janeiro | I38: =Tabela22[[#This Row],[PESO TOTAL]]/Tabela22[[#This Row],[QUANTIDADE]] -> #DIV/0!
... B571: =TEXT(Tabela22345[[#This Row],[DATA]],"mmmm") -> janeiro | I571: =Tabela22[[#This Row],[PESO TOTAL]]/Tabela22[[#This Row],[QUANTIDADE]] -> #DIV/0!

Sheet SAO JOSE DO GROTAO
A1: MOVIMENTAÇÃO FAZENDA SÃO JOSE DO GROTÃO | S1: COMPRA
D2: ENTRADAS | J2: SAIDAS | O2: POSIÇÃO | S2: NASC.
S3: TRANSF. E
A4: CATEGORIAS | D4: SALDO ANTERIOR | E4: COMPRA | F4: EVOLUÇ | G4: NASC. | H4: TRANSF. E | I4: TOTAL | J4: ABATE | K4: MORTE | L4: VENDA | M4: TRANSF. S | N4: TOTAL | O4: FINAL | S4: ABATE
A5: Femeas + 36 meses | E5: =SUMIFS($E$20:$E$1048576,$D$20:$D$1048576,$E$4,$C$20:$C$1048576,A5) -> 0 | F5: =SUMIFS($E$20:$E$1048576,$D$20:$D$1048576,$F$4,$C$20:$C$1048576,B5) -> 0 | G5: =SUMIFS($E$20:$E$1048576,$D$20:$D$1048576,$G$4,$C$20:$C$1048576,A5) -> 0 | H5: =SUMIFS($E$20:$E$1048576,$D$20:$D$1048576,$H$4,$C$20:$C$1048576,A5) -> 0 | I5: =SUM(D5:H5) -> 0 | J5: =SUMIFS($E$20:$E$1048576,$D$20:$D$1048576,$J$4,$C$20:$C$1048576,A5) -> 0 | K5: =SUMIFS($E$20:$E$1048576,$D$20:$D$1048576,$K$4,$C$20:$C$1048576,A5) -> 0 | L5: =SUMIFS($E$20:$E$1048576,$D$20:$D$1048576,$L$4,$C$20:$C$1048576,A5) -> 0 | M5: =SUMIFS($E$20:$E$1048576,$D$20:$D$1048576,$M$4,$C$20:$C$1048576,A5) -> 0 | N5: =SUM(J5:M5) -> 0 | O5: =SUM(I5-N5) -> 0 | S5: MORTE
A6: Femeas 25 a 36 meses | E6: =SUMIFS($E$20:$E$1048576,$D$20:$D$1048576,$E$4,$C$20:$C$1048576,A6) -> 0 | F6: =SUMIFS($E$20:$E$1048576,$D$20:$D$1048576,$F$4,$C$20:$C$1048576,B6) -> 0 | G6: =SUMIFS($E$20:$E$1048576,$D$20:$D$1048576,$G$4,$C$20:$C$1048576,A6) -> 0 | H6: =SUMIFS($E$20:$E$1048576,$D$20:$D$1048576,$H$4,$C$20:$C$1048576,A6) -> 0 | I6: =SUM(D6:H6) -> 0 | J6: =SUMIFS($E$20:$E$1048576,$D$20:$D$1048576,$J$4,$C$20:$C$1048576,A6) -> 0 | K6: =SUMIFS($E$20:$E$1048576,$D$20:$D$1048576,$K$4,$C$20:$C$1048576,A6) -> 0 | L6: =SUMIFS($E$20:$E$1048576,$D$20:$D$1048576,$L$4,$C$20:$C$1048576,A6) -> 0 | M6: =SUMIFS($E$20:$E$1048576,$D$20:$D$1048576,$M$4,$C$20:$C$1048576,A6) -> 0 | N6: =SUM(J6:M6) -> 0 | O6: =SUM(I6-N6) -> 0 | S6: TRANSF. S
A7: Femeas 13 a 24 meses | E7: =SUMIFS($E$20:$E$1048576,$D$20:$D$1048576,$E$4,$C$20:$C$1048576,A7) -> 0 | F7: =SUMIFS($E$20:$E$1048576,$D$20:$D$1048576,$F$4,$C$20:$C$1048576,B7) -> 0 | G7: =SUMIFS($E$20:$E$1048576,$D$20:$D$1048576,$G$4,$C$20:$C$1048576,A7) -> 0 | H7: =SUMIFS($E$20:$E$1048576,$D$20:$D$1048576,$H$4,$C$20:$C$1048576,A7) -> 0 | I7: =SUM(D7:H7) -> 0 | J7: =SUMIFS($E$20:$E$1048576,$D$20:$D$1048576,$J$4,$C$20:$C$1048576,A7) -> 0 | K7: =SUMIFS($E$20:$E$1048576,$D$20:$D$1048576,$K$4,$C$20:$C$1048576,A7) -> 0 | L7: =SUMIFS($E$20:$E$1048576,$D$20:$D$1048576,$L$4,$C$20:$C$1048576,A7) -> 0 | M7: =SUMIFS($E$20:$E$1048576,$D$20:$D$1048576,$M$4,$C$20:$C$1048576,A7) -> 0 | N7: =SUM(J7:M7) -> 0 | O7: =SUM(I7-N7) -> 0 | S7: SALDO ANTERIOR
A8: Femeas Desm. até 12m | E8: =SUMIFS($E$20:$E$1048576,$D$20:$D$1048576,$E$4,$C$20:$C$1048576,A8) -> 0 | F8: =SUMIFS($E$20:$E$1048576,$D$20:$D$1048576,$F$4,$C$20:$C$1048576,B8) -> 0 | G8: =SUMIFS($E$20:$E$1048576,$D$20:$D$1048576,$G$4,$C$20:$C$1048576,A8) -> 0 | H8: =SUMIFS($E$20:$E$1048576,$D$20:$D$1048576,$H$4,$C$20:$C$1048576,A8) -> 0 | I8: =SUM(D8:H8) -> 0 | J8: =SUMIFS($E$20:$E$1048576,$D$20:$D$1048576,$J$4,$C$20:$C$1048576,A8) -> 0 | K8: =SUMIFS($E$20:$E$1048576,$D$20:$D$1048576,$K$4,$C$20:$C$1048576,A8) -> 0 | L8: =SUMIFS($E$20:$E$1048576,$D$20:$D$1048576,$L$4,$C$20:$C$1048576,A8) -> 0 | M8: =SUMIFS($E$20:$E$1048576,$D$20:$D$1048576,$M$4,$C$20:$C$1048576,A8) -> 0 | N8: =SUM(J8:M8) -> 0 | O8: =SUM(I8-N8) -> 0 | S8: EVOLUÇ
A9: Bezerras Mamando | E9: =SUMIFS($E$20:$E$1048576,$D$20:$D$1048576,$E$4,$C$20:$C$1048576,A9) -> 0 | F9: =SUMIFS($E$20:$E$1048576,$D$20:$D$1048576,$F$4,$C$20:$C$1048576,B9) -> 0 | G9: =SUMIFS($E$20:$E$1048576,$D$20:$D$1048576,$G$4,$C$20:$C$1048576,A9) -> 0 | H9: =SUMIFS($E$20:$E$1048576,$D$20:$D$1048576,$H$4,$C$20:$C$1048576,A9) -> 0 | I9: =SUM(D9:H9) -> 0 | J9: =SUMIFS($E$20:$E$1048576,$D$20:$D$1048576,$J$4,$C$20:$C$1048576,A9) -> 0 | K9: =SUMIFS($E$20:$E$1048576,$D$20:$D$1048576,$K$4,$C$20:$C$1048576,A9) -> 0 | L9: =SUMIFS($E$20:$E$1048576,$D$20:$D$1048576,$L$4,$C$20:$C$1048576,A9) -> 0 | M9: =SUMIFS($E$20:$E$1048576,$D$20:$D$1048576,$M$4,$C$20:$C$1048576,A9) -> 0 | N9: =SUM(J9:M9) -> 0 | O9: =SUM(I9-N9) -> 0 | S9: VENDA
A10: Bezerros Mamando | E10: =SUMIFS($E$20:$E$1048576,$D$20:$D$1048576,$E$4,$C$20:$C$1048576,A10) -> 0 | F10: =SUMIFS($E$20:$E$1048576,$D$20:$D$1048576,$F$4,$C$20:$C$1048576,B10) -> 0 | G10: =SUMIFS($E$20:$E$1048576,$D$20:$D$1048576,$G$4,$C$20:$C$1048576,A10) -> 0 | H10: =SUMIFS($E$20:$E$1048576,$D$20:$D$1048576,$H$4,$C$20:$C$1048576,A10) -> 0 | I10: =SUM(D10:H10) -> 0 | J10: =SUMIFS($E$20:$E$1048576,$D$20:$D$1048576,$J$4,$C$20:$C$1048576,A10) -> 0 | K10: =SUMIFS($E$20:$E$1048576,$D$20:$D$1048576,$K$4,$C$20:$C$1048576,A10) -> 0 | L10: =SUMIFS($E$20:$E$1048576,$D$20:$D$1048576,$L$4,$C$20:$C$1048576,A10) -> 0 | M10: =SUMIFS($E$20:$E$1048576,$D$20:$D$1048576,$M$4,$C$20:$C$1048576,A10) -> 0 | N10: =SUM(J10:M10) -> 0 | O10: =SUM(I10-N10) -> 0
A11: Machos Desm. até 12m | E11: =SUMIFS($E$20:$E$1048576,$D$20:$D$1048576,$E$4,$C$20:$C$1048576,A11) -> 0 | F11: =SUMIFS($E$20:$E$1048576,$D$20:$D$1048576,$F$4,$C$20:$C$1048576,B11) -> 0 | G11: =SUMIFS($E$20:$E$1048576,$D$20:$D$1048576,$G$4,$C$20:$C$1048576,A11) -> 0 | H11: =SUMIFS($E$20:$E$1048576,$D$20:$D$1048576,$H$4,$C$20:$C$1048576,A11) -> 0 | I11: =SUM(D11:H11) -> 0 | J11: =SUMIFS($E$20:$E$1048576,$D$20:$D$1048576,$J$4,$C$20:$C$1048576,A11) -> 0 | K11: =SUMIFS($E$20:$E$1048576,$D$20:$D$1048576,$K$4,$C$20:$C$1048576,A11) -> 0 | L11: =SUMIFS($E$20:$E$1048576,$D$20:$D$1048576,$L$4,$C$20:$C$1048576,A11) -> 0 | M11: =SUMIFS($E$20:$E$1048576,$D$20:$D$1048576,$M$4,$C$20:$C$1048576,A11) -> 0 | N11: =SUM(J11:M11) -> 0 | O11: =SUM(I11-N11) -> 0
A12: Machos 13 a 24 meses | E12: =SUMIFS($E$20:$E$1048576,$D$20:$D$1048576,$E$4,$C$20:$C$1048576,A12) -> 0 | F12: =SUMIFS($E$20:$E$1048576,$D$20:$D$1048576,$F$4,$C$20:$C$1048576,B12) -> 0 | G12: =SUMIFS($E$20:$E$1048576,$D$20:$D$1048576,$G$4,$C$20:$C$1048576,A12) -> 0 | H12: =SUMIFS($E$20:$E$1048576,$D$20:$D$1048576,$H$4,$C$20:$C$1048576,A12) -> 0 | I12: =SUM(D12:H12) -> 0 | J12: =SUMIFS($E$20:$E$1048576,$D$20:$D$1048576,$J$4,$C$20:$C$1048576,A12) -> 0 | K12: =SUMIFS($E$20:$E$1048576,$D$20:$D$1048576,$K$4,$C$20:$C$1048576,A12) -> 0 | L12: =SUMIFS($E$20:$E$1048576,$D$20:$D$1048576,$L$4,$C$20:$C$1048576,A12) -> 0 | M12: =SUMIFS($E$20:$E$1048576,$D$20:$D$1048576,$M$4,$C$20:$C$1048576,A12) -> 0 | N12: =SUM(J12:M12) -> 0 | O12: =SUM(I12-N12) -> 0
A13: Machos 25 a 36 meses | E13: =SUMIFS($E$20:$E$1048576,$D$20:$D$1048576,$E$4,$C$20:$C$1048576,A13) -> 0 | F13: =SUMIFS($E$20:$E$1048576,$D$20:$D$1048576,$F$4,$C$20:$C$1048576,B13) -> 0 | G13: =SUMIFS($E$20:$E$1048576,$D$20:$D$1048576,$G$4,$C$20:$C$1048576,A13) -> 0 | H13: =SUMIFS($E$20:$E$1048576,$D$20:$D$1048576,$H$4,$C$20:$C$1048576,A13) -> 0 | I13: =SUM(D13:H13) -> 0 | J13: =SUMIFS($E$20:$E$1048576,$D$20:$D$1048576,$J$4,$C$20:$C$1048576,A13) -> 0 | K13: =SUMIFS($E$20:$E$1048576,$D$20:$D$1048576,$K$4,$C$20:$C$1048576,A13) -> 0 | L13: =SUMIFS($E$20:$E$1048576,$D$20:$D$1048576,$L$4,$C$20:$C$1048576,A13) -> 0 | M13: =SUMIFS($E$20:$E$1048576,$D$20:$D$1048576,$M$4,$C$20:$C$1048576,A13) -> 0 | N13: =SUM(J13:M13) -> 0 | O13: =SUM(I13-N13) -> 0
A14: Touros | E14: =SUMIFS($E$20:$E$1048576,$D$20:$D$1048576,$E$4,$C$20:$C$1048576,A14) -> 0 | F14: =SUMIFS($E$20:$E$1048576,$D$20:$D$1048576,$F$4,$C$20:$C$1048576,B14) -> 0 | G14: =SUMIFS($E$20:$E$1048576,$D$20:$D$1048576,$G$4,$C$20:$C$1048576,A14) -> 0 | H14: =SUMIFS($E$20:$E$1048576,$D$20:$D$1048576,$H$4,$C$20:$C$1048576,A14) -> 0 | I14: =SUM(D14:H14) -> 0 | J14: =SUMIFS($E$20:$E$1048576,$D$20:$D$1048576,$J$4,$C$20:$C$1048576,A14) -> 0 | K14: =SUMIFS($E$20:$E$1048576,$D$20:$D$1048576,$K$4,$C$20:$C$1048576,A14) -> 0 | L14: =SUMIFS($E$20:$E$1048576,$D$20:$D$1048576,$L$4,$C$20:$C$1048576,A14) -> 0 | M14: =SUMIFS($E$20:$E$1048576,$D$20:$D$1048576,$M$4,$C$20:$C$1048576,A14) -> 0 | N14: =SUM(J14:M14) -> 0 | O14: =SUM(I14-N14) -> 0
A15: TROPA | E15: =SUMIFS($E$20:$E$1048576,$D$20:$D$1048576,$E$4,$C$20:$C$1048576,A15) -> 0 | G15: =SUMIFS($E$20:$E$1048576,$D$20:$D$1048576,$G$4,$C$20:$C$1048576,A15) -> 0 | H15: =SUMIFS($E$20:$E$1048576,$D$20:$D$1048576,$H$4,$C$20:$C$1048576,A15) -> 0 | I15: =SUM(D15:H15) -> 0 | J15: =SUMIFS($E$20:$E$1048576,$D$20:$D$1048576,$J$4,$C$20:$C$1048576,A15) -> 0 | K15: =SUMIFS($E$20:$E$1048576,$D$20:$D$1048576,$K$4,$C$20:$C$1048576,A15) -> 0 | L15: =SUMIFS($E$20:$E$1048576,$D$20:$D$1048576,$L$4,$C$20:$C$1048576,A15) -> 0 | M15: =SUMIFS($E$20:$E$1048576,$D$20:$D$1048576,$M$4,$C$20:$C$1048576,A15) -> 0 | N15: =SUM(J15:M15) -> 0 | O15: =SUM(I15-N15) -> 0
A16: TOTAL | D16: =SUM(D5:D15) -> 0 | E16: =SUM(E5:E15) -> 0 | F16: =SUM(F5:F15) -> 0 | G16: =SUM(G5:G15) -> 0 | H16: =SUM(H5:H15) -> 0 | I16: =SUM(I5:I15) -> 0 | J16: =SUM(J5:J15) -> 0 | K16: =SUM(K5:K15) -> 0 | ... M16: =SUM(M5:M15) -> 0 | N16: =SUM(J16:M16) -> 0 | O16: =SUM(O5:O14) -> 0
A18: MOVIMENTAÇÕES DE BOVINOS
A19: DATA | B19: MÊS | C19: CATEGORIA | D19: TIPO | E19: QUANTIDADE | F19: SAIDA | G19: DESTINO | H19: PESO TOTAL | I19: PESO MÉDIO
B20: =TEXT(Tabela223456[[#This Row],[DATA]],"mmm") -> jan | I20: =Tabela22[[#This Row],[PESO TOTAL]]/Tabela22[[#This Row],[QUANTIDADE]] -> #VALUE!
B21: =TEXT(Tabela223456[[#This Row],[DATA]],"mmm") -> jan | I21: =Tabela22[[#This Row],[PESO TOTAL]]/Tabela22[[#This Row],[QUANTIDADE]] -> 0
B22: =TEXT(Tabela223456[[#This Row],[DATA]],"mmm") -> jan | I22: =Tabela22[[#This Row],[PESO TOTAL]]/Tabela22[[#This Row],[QUANTIDADE]] -> #DIV/0!
B23: =TEXT(Tabela223456[[#This Row],[DATA]],"mmm") -> jan | I23: =Tabela22[[#This Row],[PESO TOTAL]]/Tabela22[[#This Row],[QUANTIDADE]] -> #DIV/0!
B24: =TEXT(Tabela223456[[#This Row],[DATA]],"mmm") -> jan | I24: =Tabela22[[#This Row],[PESO TOTAL]]/Tabela22[[#This Row],[QUANTIDADE]] -> #DIV/0!
B25: =TEXT(Tabela223456[[#This Row],[DATA]],"mmm") -> jan | I25: =Tabela22[[#This Row],[PESO TOTAL]]/Tabela22[[#This Row],[QUANTIDADE]] -> #DIV/0!
B26: =TEXT(Tabela223456[[#This Row],[DATA]],"mmm") -> jan | I26: =Tabela22[[#This Row],[PESO TOTAL]]/Tabela22[[#This Row],[QUANTIDADE]] -> #DIV/0!
